Workbook
Name \0: #REF!
Name \e: #REF!
Name \r: [1]Workings!#REF!
Name ____pr1: '[2]contract sum claim'!#REF!
Name ___VAR3: #N/A
Name ___VAR4: #N/A
Name __pr1: '[2]contract sum claim'!#REF!
Name __VAR3: #N/A
Name __VAR4: #N/A
Name _dj2: #REF!
Name _Hlk54693717: SOR!$C$12
Name _pr1: '[4]contract sum claim'!#REF!
Name _pr1: '[4]contract sum claim'!#REF!
Name _pr1: '[4]contract sum claim'!#REF!
Name _pr1: '[4]contract sum claim'!#REF!
Name _pr1: '[4]contract sum claim'!#REF!
Name _pr1: '[4]contract sum claim'!#REF!
Name _pr1: '[4]contract sum claim'!#REF!
Name _pr1: '[4]contract sum claim'!#REF!
Name _pr1: '[4]contract sum claim'!#REF!
Name _pr1: '[4]contract sum claim'!#REF!
Name _pr1: '[2]contract sum claim'!#REF!
Name _Regression_Int: 1
Name _VAR3: #N/A
Name _VAR4: #N/A
Name a: #REF!
Name aa: #REF!
Name apm: #REF!
Name apm_bax.contract: #REF!
Name apm_bax.now: #REF!
Name apm_bax.old: #REF!
Name apm_bax.old.now: #REF!
Name apm_bax.old.payment: #REF!
Name apm_bax.old.vo.app: #REF!
Name apm_bax.payment: #REF!
Name apm_bax.rev: #REF!
Name apm_bax.tot.contract: #REF!
Name apm_bax.tot.now: #REF!
Name apm_bax.tot.payment: #REF!
Name apm_bax.tot.vo.app: #REF!
Name apm_bax.vo.app: #REF!
Name apm_ccu.bs: #REF!
Name apm_ccu.bs.now: #REF!
Name apm_ccu.bs.payment: #REF!
Name apm_ccu.bs.vo.app: #REF!
Name apm_ccu.cert: #REF!
Name apm_ccu.contract: #REF!
Name apm_ccu.contract.now: #REF!
Name apm_ccu.fire: #REF!
Name apm_ccu.fire.now: #REF!
Name apm_ccu.fire.payment: #REF!
Name apm_ccu.fire.vo.app: #REF!
Name apm_ccu.furn: #REF!
Name apm_ccu.furn.vo.app: #REF!
Name apm_ccu.mon: #REF!
Name apm_ccu.mon.vo.app: #REF!
Name apm_ccu.payment: #REF!
Name apm_ccu.rev: #REF!
Name apm_ccu.tot.contract: #REF!
Name apm_ccu.tot.now: #REF!

Sheet  Summary
B2: SINSW08089/25 New Primary School in Calderwood - Tender Schedules 3 - (Lump Sum)
B3: Tenderer: | C3: [Insert]
B5: MAIN WORKS SUMMARY
B7: Item | C7: Description | D7: Total ($)
B8: 1 | C8: Preliminaries | D8: =Preliminaries!F81 -> 0
B9: =++B8+1 -> 2 | C9: Margin | D9: ='Main Works'!H65 -> 0
B10: =++B9+1 -> 3 | C10: Delivery Consultants | D10: =Consultants!D38 -> 0
B11: =++B10+1 -> 4 | C11: Trade Cost | D11: ='Main Works'!H62 -> 0
C12: TOTAL MAIN WORKS (EXCL. GST) | D12: =++SUBTOTAL(9,D8:D11) -> 0
B13: =++B11+1 -> 5 | C13: GST | D13: =++D12*10% -> 0
C14: TOTAL MAIN WORKS (INCL. GST) | D14: =++SUBTOTAL(9,D8:D13) -> 0
B16: PRINCIPAL'S PRICED OPTIONS
B18: Item | C18: Description | D18: Total ($)
B19: PPO#1 | C19: ='Sched 4 PPO'!B6 -> Stage 2 FHR infrastructure supply | D19: ='Sched 4 PPO'!G6 -> 0
B20: PPO#2 | C20: ='Sched 4 PPO'!B7 -> Stage 2 Water Services Infrastructure supply | D20: ='Sched 4 PPO'!G7 -> 0
B21: PPO#3 | C21: ='Sched 4 PPO'!B8 -> Stage 2 Power, Comm and Security infrastructure supply | D21: ='Sched 4 PPO'!G8 -> 0
B22: PPO#4 | C22: ='Sched 4 PPO'!B9 -> Deletion of Hose Reel and associated underground reticulation to all buildings. | D22: ='Sched 4 PPO'!G9 -> 0
B23: PPO#5 | C23: ='Sched 4 PPO'!B10 -> 50kVA Diesel Generator to Preschool, including day tank and all the associated works | D23: ='Sched 4 PPO'!G10 -> 0
B24: PPO#6 | C24: ='Sched 4 PPO'!B11 -> Canopy to Admin (approx. 120sqm) | D24: ='Sched 4 PPO'!G11 -> 0
B25: PPO#7 | C25: ='Sched 4 PPO'!B12 -> Sandblast stencil finish to main pathway, currently brushed coloured concrete (approx. 630 sqm) | D25: ='Sched 4 PPO'!G12 -> 0
B26: PPO#8 | C26: ='Sched 4 PPO'!B13 -> Allow 3 x 800L trees and 27 x 400L trees in lieu of 75L trees, including tree pit. | D26: ='Sched 4 PPO'!G13 -> 0
C27: TOTAL PPO (EXCL. GST) | D27: =SUM(D19:D26) -> 0
C28: GST | D28: =++D27*10% -> 0
C29: TOTAL PPO (INCL. GST) | D29: =D27+D28 -> 0

Sheet Main Works
A1: SINSW08089/25 New Primary School in Calderwood - Tender Schedules 3 - (Lump Sum)
B3: =' Summary'!C3 -> [Insert]
A5: Main Works
A7: # | B7: Description | C7: Building A1 | D7: Building A2 | E7: Hall, Canteen & COLA | F7: Preschool | G7: Demolition, External Works & External Services | H7: Total (Ex. GST)
A8: 1 | B8: Demolition | G8: 0 | H8: =G8 -> 0
A9: =A8+1 -> 2 | B9: Site Preparation / Bulk Excavation | G9: 0 | H9: =G9 -> 0
A10: =A9+1 -> 3 | B10: Site Remediation | G10: 0 | H10: =G10 -> 0
A11: =A10+1 -> 4 | B11: Detailed Earthworks | C11: 0 | D11: 0 | E11: 0 | F11: 0 | G11: 0 | H11: =C11+D11+E11+F11+G11 -> 0
A12: =A11+1 -> 5 | B12: Piling | C12: 0 | D12: 0 | E12: 0 | F12: 0 | H12: =C12+D12+E12+F12 -> 0
A13: 6.1 | B13: Concrete | C13: 0 | D13: 0 | E13: 0 | F13: 0 | H13: =C13+D13+E13+F13 -> 0
A14: 6.2 | B14: Formwork | C14: 0 | D14: 0 | E14: 0 | F14: 0 | H14: =C14+D14+E14+F14 -> 0
A15: 6.3 | B15: Reinforcement | C15: 0 | D15: 0 | E15: 0 | F15: 0 | H15: =C15+D15+E15+F15 -> 0
A16: 6.4 | B16: Post Tensioning | C16: 0 | D16: 0 | E16: 0 | F16: 0 | H16: =C16+D16+E16+F16 -> 0
A17: 7 | B17: Masonry | C17: 0 | D17: 0 | E17: 0 | F17: 0 | H17: =C17+D17+E17+F17 -> 0
A18: =A17+1 -> 8 | B18: Structural Steel | C18: 0 | D18: 0 | E18: 0 | F18: 0 | H18: =C18+D18+E18+F18 -> 0
A19: =A18+1 -> 9 | B19: Waterproof Membranes | C19: 0 | D19: 0 | E19: 0 | F19: 0 | H19: =C19+D19+E19+F19 -> 0
A20: =A19+1 -> 10 | B20: Roofing & Roof Plumbing | C20: 0 | D20: 0 | E20: 0 | F20: 0 | H20: =C20+D20+E20+F20 -> 0
A21: =A20+1 -> 11 | B21: External Cladding & Soffit | C21: 0 | D21: 0 | E21: 0 | F21: 0 | H21: =C21+D21+E21+F21 -> 0
A22: =A21+1 -> 12 | B22: Windows Glazing and Glazed Doors | C22: 0 | D22: 0 | E22: 0 | F22: 0 | H22: =C22+D22+E22+F22 -> 0
A23: =A22+1 -> 13 | B23: Doors, Frames and Hardware | C23: 0 | D23: 0 | E23: 0 | F23: 0 | H23: =C23+D23+E23+F23 -> 0
A24: =A23+1 -> 14 | B24: Partitions and Linings | C24: 0 | D24: 0 | E24: 0 | F24: 0 | H24: =C24+D24+E24+F24 -> 0
A25: =A24+1 -> 15 | B25: Operable Walls and Overhead Doors | C25: 0 | D25: 0 | E25: 0 | F25: 0 | H25: =C25+D25+E25+F25 -> 0
A26: =A25+1 -> 16 | B26: Ceilings | C26: 0 | D26: 0 | E26: 0 | F26: 0 | H26: =C26+D26+E26+F26 -> 0
A27: =A26+1 -> 17 | B27: Tiling | C27: 0 | D27: 0 | E27: 0 | F27: 0 | H27: =C27+D27+E27+F27 -> 0
A28: =A27+1 -> 18 | B28: Carpet | C28: 0 | D28: 0 | E28: 0 | F28: 0 | H28: =C28+D28+E28+F28 -> 0
A29: =A28+1 -> 19 | B29: Resilient Flooring | C29: 0 | D29: 0 | E29: 0 | F29: 0 | H29: =C29+D29+E29+F29 -> 0
... A45: =A44+1 -> 35 | B45: Mechanical Services | C45: 0 | D45: 0 | E45: 0 | F45: 0 | H45: =C45+D45+E45+F45 -> 0
A46: 36.1 | B46: FF&E - Group 1 Supply & Installed by Contractor | C46: 0 | D46: 0 | E46: 0 | F46: 0 | H46: =C46+D46+E46+F46 -> 0
A47: 36.2 | B47: FF&E - Group 2 Provided by Principal and installed by Contractor | C47: 0 | D47: 0 | E47: 0 | F47: 0 | H47: =C47+D47+E47+F47 -> 0
A48: 37 | B48: Soft Landscaping | G48: 0 | H48: =G48 -> 0
A49: =A48+1 -> 38 | B49: Hard landscaping [Footpaths & Pavements] | G49: 0 | H49: =G49 -> 0
A50: =A49+1 -> 39 | B50: Works Outside of School Boundary - e.g. Kiss & Drop, Crossing etc | G50: 0 | H50: =G50 -> 0
A51: =A50+1 -> 40 | B51: External Stormwater & Drainage | G51: 0 | H51: =G51 -> 0
A52: =A51+1 -> 41 | B52: Supply and install OSD tank and associated work | G52: 0 | H52: =G52 -> 0
A53: =A52+1 -> 42 | B53: External Sewer Drainage | G53: 0 | H53: =G53 -> 0
A54: =A53+1 -> 43 | B54: External Water Supply | G54: 0 | H54: =G54 -> 0
A55: =A54+1 -> 44 | B55: External Gas | G55: 0 | H55: =G55 -> 0
A56: 45 | B56: External Fire Protection | G56: 0 | H56: =G56 -> 0
A57: 46 | B57: External Electric Light & Power, Communications and Security Services | G57: 0 | H57: =G57 -> 0
A58: 47 | B58: Substation | G58: 0 | H58: =G58 -> 0
...

Sheet Preliminaries
A1: ='Main Works'!A1 -> SINSW08089/25 New Primary School in Calderwood - Tender Schedules 3 - (Lump Sum)
B3: =' Summary'!C3 -> [Insert]
A5: Preliminaries
A7: # | B7: Description | C7: No. of Staff | D7: Rate per Week | E7: No. of Weeks | F7: Total (Ex. GST)
A8: 1 | B8: PRE-CONSTRUCTION
A9: =A8+1 -> 2 | B9: Executive Representation | F9: =C9*D9*E9 -> 0
A10: =A9+1 -> 3 | B10: Project Manager | F10: =C10*D10*E10 -> 0
A11: =A10+1 -> 4 | B11: Design Manager | F11: =C11*D11*E11 -> 0
A12: =A11+1 -> 5 | B12: Project Engineer | F12: =C12*D12*E12 -> 0
A13: =A12+1 -> 6 | B13: Stakeholder Manager | F13: =C13*D13*E13 -> 0
A14: =A13+1 -> 7 | B14: Other - Please Specify | F14: =C14*D14*E14 -> 0
A15: =A14+1 -> 8 | B15: CONSTRUCTION
A16: =A15+1 -> 9 | B16: Project Manager | F16: =C16*D16*E16 -> 0
A17: =A16+1 -> 10 | B17: Design Manager | F17: =C17*D17*E17 -> 0
A18: =A17+1 -> 11 | B18: Construction Manager | F18: =C18*D18*E18 -> 0
A19: =A18+1 -> 12 | B19: Site Manager | F19: =C19*D19*E19 -> 0
A20: =A19+1 -> 13 | B20: Contracts Administrator | F20: =C20*D20*E20 -> 0
A21: =A20+1 -> 14 | B21: Foreman | F21: =C21*D21*E21 -> 0
A22: =A21+1 -> 15 | B22: WHS Manager | F22: =C22*D22*E22 -> 0
A23: =A22+1 -> 16 | B23: Programmer | F23: =C23*D23*E23 -> 0
A24: =A23+1 -> 17 | B24: Engineers | F24: =C24*D24*E24 -> 0
A25: =A24+1 -> 18 | B25: Site Labour | F25: =C25*D25*E25 -> 0
A26: =A25+1 -> 19 | B26: Other - Please Specify | F26: =C26*D26*E26 -> 0
A27: =A26+1 -> 20 | B27: Other - Please Specify | F27: =C27*D27*E27 -> 0
A28: =A27+1 -> 21 | B28: Insurances & Bank Guarantees
A29: =A28+1 -> 22 | B29: Bank Guarantees | F29: 0
A30: =A29+1 -> 23 | B30: Workers Compensation Insurances | F30: 0
A31: =A30+1 -> 24 | B31: Professional Indemnity Insurances | F31: 0
A32: =A31+1 -> 25 | B32: Public Liability | F32: 0
A33: =A32+1 -> 26 | B33: Work Insurance | F33: 0
A34: =A33+1 -> 27 | B34: Other Insurances - please advise what they are | F34: 0
A35: =A34+1 -> 28 | B35: Site Establishment
A36: =A35+1 -> 29 | B36: Hoardings and Site Fencing | F36: 0
A37: =A36+1 -> 30 | B37: Safety Barriers / Rails | F37: 0
A38: =A37+1 -> 31 | B38: Site Establishment & Disestablishment | F38: 0
A39: =A38+1 -> 32 | B39: Project Office, Compound and Amenities | F39: 0
A40: =A39+1 -> 33 | B40: Contractors Signage (Project Signboards, Statutory, Directional and Wayfinding | F40: 0
A41: =A40+1 -> 34 | B41: Site Running Costs
A42: =A41+1 -> 35 | B42: Site Office Expenses including Computers and IT | F42: 0
A43: =A42+1 -> 36 | B43: Site Security | F43: 0
...

Sheet Consultants
A1: ='Main Works'!A1 -> SINSW08089/25 New Primary School in Calderwood - Tender Schedules 3 - (Lump Sum)
B3: =' Summary'!C3 -> [Insert]
A5: Consultants
A7: # | B7: Discipline | C7: Name of Consultant Company | D7: Total (Ex. GST)
A8: 1 | B8: Architectural Services
A9: =A8+1 -> 2 | B9: Landscape Architect
A10: =A9+1 -> 3 | B10: Civil Engineering Services
A11: =A10+1 -> 4 | B11: Structural Engineering Services
A12: =A11+1 -> 5 | B12: Engineering Services (Electrical, ICT, AV, Dry Fire and Security)
A13: =A12+1 -> 6 | B13: Engineering Services (Mechanical and BMS)
A14: =A13+1 -> 7 | B14: Engineering Services (Hydraulic & Wet Fire)
A15: =A14+1 -> 8 | B15: Fire Safety Engineering
A16: =A15+1 -> 9 | B16: Heritage Consultant
A17: =A16+1 -> 10 | B17: BCA Consultant
A18: =A17+1 -> 11 | B18: PCA Consultant Crown Certifier
A19: =A18+1 -> 12 | B19: Access Consultant
A20: =A19+1 -> 13 | B20: Acoustic Consultant
... A37: =A36+1 -> 30 | B37: Other - please specify
A38: =A37+1 -> 31 | B38: Total Consultant Fees (Excl. GST) | D38: =SUM(D8:D37) -> 0

Sheet Sched 4 PPO
A1: SINSW08089/25 New Primary School in Calderwood - Tender Schedule 4 - (Principal's Priced Options)
B3: ='Main Works'!B3 -> [Insert]
A5: # | B5: Principal's Priced Option | C5: Trades | D5: Preliminaries | E5: Margin | F5: Design Fee | G5: Total (Ex. GST)
A6: 1 | B6: Stage 2 FHR infrastructure supply | G6: =C6+D6+E6+F6 -> 0 | H6: Savings
A7: 2 | B7: Stage 2 Water Services Infrastructure supply | G7: =C7+D7+E7+F7 -> 0 | H7: Savings
A8: =A7+1 -> 3 | B8: Stage 2 Power, Comm and Security infrastructure supply | G8: =C8+D8+E8+F8 -> 0 | H8: Savings
A9: =A8+1 -> 4 | B9: Deletion of Hose Reel and associated underground reticulation to all buildings. | G9: =C9+D9+E9+F9 -> 0 | H9: Savings
A10: =A9+1 -> 5 | B10: 50kVA Diesel Generator to Preschool, including day tank and all the associated works | G10: =C10+D10+E10+F10 -> 0 | H10: Savings
A11: =A10+1 -> 6 | B11: Canopy to Admin (approx. 120sqm) | G11: =C11+D11+E11+F11 -> 0 | H11: Addition
A12: =A11+1 -> 7 | B12: Sandblast stencil finish to main pathway, currently brushed coloured concrete (approx. 630 sqm) | G12: =C12+D12+E12+F12 -> 0 | H12: Addition
A13: =A12+1 -> 8 | B13: Allow 3 x 800L trees and 27 x 400L trees in lieu of 75L trees, including tree pit. | G13: =C13+D13+E13+F13 -> 0 | H13: Addition
B14: Total PPO - Construction Works Cost including Design Costs, Preliminaries, Supervision, Margin and Overheads (Excl. GST) | C14: =SUM(C6:C13) -> 0 | D14: =SUM(D6:D13) -> 0 | E14: =SUM(E6:E13) -> 0 | F14: =SUM(F6:F13) -> 0 | G14: =SUM(G6:G13) -> 0

Sheet Sched 7 Mand Alt
A1: SINSW08089-25 New Primary School in Calderwood - Tender Schedule 8 - (Mandatory Alternative Tenders)
B3: ='Main Works'!B3 -> [Insert]
A5: # | B5: Mandatory Alternative Tenders | C5: Trades | D5: Preliminaries | E5: Margin | F5: Design Fee | G5: Total (Ex. GST)
A6: 1 | B6: Gable roof structure design as an alternative to Buildings A1 and A2 | G6: =C6+D6+E6+F6 -> 0
A7: =A6+1 -> 2 | B7: Removal of point of use hot water units to Access WC's without showers x 6 no | G7: =C7+D7+E7+F7 -> 0
A8: =A7+1 -> 3 | B8: Carpark - replace permeable pavers with asphalt paving | G8: =C8+D8+E8+F8 -> 0
A9: =A8+1 -> 4 | B9: Preschool Play Area - scaled back to 420sqm Pattern Book provision | G9: =C9+D9+E9+F9 -> 0
A10: =A9+1 -> 5 | B10: 2100mm Boundary Fence - Diplomat alternative to 358 fence | G10: =C10+D10+E10+F10 -> 0
A11: =A10+1 -> 6 | B11: Delete trees and native grass to Stage 2 area outdoor and replace with EFSG compliant seeded grass | G11: =C11+D11+E11+F11 -> 0
A12: =A11+1 -> 7 | B12: Delete external brick and sandstone seating walls. Replace with metal seating compliant to ESFG and DDA. | G12: =C12+D12+E12+F12 -> 0
A13: =A12+1 -> 8 | B13: Propose proprietary corrugated iron raised planter beds in stage 2 area - in place of bespoke planter beds. | G13: =C13+D13+E13+F13 -> 0
A14: =A13+1 -> 9 | B14: Delete preschool western storage room (not in pattern book) | G14: =C14+D14+E14+F14 -> 0
A15: =A14+1 -> 10 | B15: Reduce preschool southern entry courtyard to minimum preschool design brief requirement. | G15: =C15+D15+E15+F15 -> 0
A16: =A15+1 -> 11 | B16: Delete wooden deck from library courtyard and replace with EFSG and DDA compliant seating. Remove recycled brick paving from library courtyard and replace with brushed coloured concrete as per CP3. | G16: =C16+D16+E16+F16 -> 0
A17: =A16+1 -> 12 | B17: Shade structures in Preschool outdoor play space to be reduced so that total shade canopy is 60% of 420sqm rather than 60% of 856sqm as currently documented. | G17: =C17+D17+E17+F17 -> 0
B18: Total - Construction Works Cost including Design Costs, Preliminaries, Supervision, Margin and Overheads (Excl. GST) | C18: =SUM(C6:C17) -> 0 | D18: =SUM(D6:D17) -> 0 | E18: =SUM(E6:E17) -> 0 | F18: =SUM(F6:F17) -> 0 | G18: =SUM(G6:G17) -> 0

Sheet VE
A1: SINSW08089-25 New Primary School in Calderwood - Value Engineering
B3: ='Main Works'!B3 -> [Insert]
A5: # | B5: Value Engineering Items | C5: Trades | D5: Preliminaries | E5: Margin | F5: Design Fee | G5: Total (Ex. GST)
A6: 1 | B6: Tenderer to insert VE item | G6: =C6+D6+E6+F6 -> 0
A7: =A6+1 -> 2 | B7: Tenderer to insert VE item | G7: =C7+D7+E7+F7 -> 0
A8: =A7+1 -> 3 | B8: Tenderer to insert VE item | G8: =C8+D8+E8+F8 -> 0
A9: =A8+1 -> 4 | B9: Tenderer to insert VE item | G9: =C9+D9+E9+F9 -> 0
A10: =A9+1 -> 5 | B10: Tenderer to insert VE item | G10: =C10+D10+E10+F10 -> 0
A11: =A10+1 -> 6 | B11: Tenderer to insert VE item | G11: =C11+D11+E11+F11 -> 0
A12: =A11+1 -> 7 | B12: Tenderer to insert VE item | G12: =C12+D12+E12+F12 -> 0
A13: =A12+1 -> 8 | B13: Tenderer to insert VE item | G13: =C13+D13+E13+F13 -> 0
A14: =A13+1 -> 9 | B14: Tenderer to insert VE item | G14: =C14+D14+E14+F14 -> 0
A15: =A14+1 -> 10 | B15: Tenderer to insert VE item | G15: =C15+D15+E15+F15 -> 0
A16: =A15+1 -> 11 | B16: Tenderer to insert VE item | G16: =C16+D16+E16+F16 -> 0
A17: =A16+1 -> 12 | B17: Tenderer to insert VE item | G17: =C17+D17+E17+F17 -> 0
A18: =A17+1 -> 13 | B18: Tenderer to insert VE item | G18: =C18+D18+E18+F18 -> 0
A19: =A18+1 -> 14 | B19: Tenderer to insert VE item | G19: =C19+D19+E19+F19 -> 0
A20: =A19+1 -> 15 | B20: Tenderer to insert VE item | G20: 0
A21: =A20+1 -> 16 | B21: Tenderer to insert VE item | G21: =C21+D21+E21+F21 -> 0
B22: Total VE Savings - Construction Works Cost including Design Costs, Preliminaries, Supervision, Margin and Overheads (Excl. GST) | C22: =SUM(C6:C21) -> 0 | D22: =SUM(D6:D21) -> 0 | E22: =SUM(E6:E21) -> 0 | F22: =SUM(F6:F21) -> 0 | G22: =SUM(G6:G21) -> 0

Sheet Elect Breakdown
A1: ='Main Works'!A1 -> SINSW08089/25 New Primary School in Calderwood - Tender Schedules 3 - (Lump Sum)
B3: ='Main Works'!B3 -> [Insert]
A5: Electrical Services
A7: # | B7: Discipline | C7: Total (Ex. GST)
A8: 1 | B8: Ausgrid works (Power Supply Works outside of School Boundary)
A9: =A8+1 -> 2 | B9: Substation
A10: =A9+1 -> 3 | B10: Work at MSB
A11: =A10+1 -> 4 | B11: Sub-Main Cables
A12: =A11+1 -> 5 | B12: Distribution Boards
A13: =A12+1 -> 6 | B13: Sub Circuit Cabling
A14: =A13+1 -> 7 | B14: Internal Lighting
A15: =A14+1 -> 8 | B15: External Lighting
A16: =A15+1 -> 9 | B16: Emergency and Exit lighting
A17: =A16+1 -> 10 | B17: Lighting Control
A18: =A17+1 -> 11 | B18: Communication cables to the hall
A19: =A18+1 -> 12 | B19: Cable Support Infrastructure
A20: =A19+1 -> 13 | B20: Power Outlets
... A35: =A34+1 -> 28 | B35: Other Items, Please Specify
A36: =A35+1 -> 29 | B36: Total Electrical Services (Excl. GST) | C36: =SUM(C8:C35) -> 0 | D36: Note: this value should equal to the Total of Items 31-34, 46, 47 and 48 in the "Main Works" tab.

Sheet Mech Breakdown
A1: ='Main Works'!A1 -> SINSW08089/25 New Primary School in Calderwood - Tender Schedules 3 - (Lump Sum)
B3: ='Main Works'!B3 -> [Insert]
A5: Mechanical Services
A7: # | B7: Discipline | C7: Total (Ex. GST)
A8: 1 | B8: Powered Roof Ventilators and Louvres
A9: =A8+1 -> 2 | B9: Ceiling / Wall Fans
A10: =A9+1 -> 3 | B10: Electric Heating System
A11: =A10+1 -> 4 | B11: Mechanical Exhaust Systems
A12: =A11+1 -> 5 | B12: Mechanical Outside Air
A13: =A12+1 -> 6 | B13: Air Conditioning Systems
A14: =A13+1 -> 7 | B14: Design Finalisation
A15: =A14+1 -> 8 | B15: Testing and Commissioing
A16: =A15+1 -> 9 | B16: Other Items, Please Specify
A17: =A16+1 -> 10 | B17: Total Mechanical Services (Excl. GST) | C17: =SUM(C8:C16) -> 0 | D17: Note: this value should match Item 35 in the "Main Works" tab.

Sheet Hydraulic Breakdown
A1: ='Main Works'!A1 -> SINSW08089/25 New Primary School in Calderwood - Tender Schedules 3 - (Lump Sum)
B3: ='Main Works'!B3 -> [Insert]
A5: Hydraulic Services
A7: # | B7: Discipline | C7: Total (Ex. GST)
A8: 1 | B8: Sanitary Plumbing and Drainage - Building Works
A9: =A8+1 -> 2 | B9: Cold Water - Building Works
A10: =A9+1 -> 3 | B10: Hot Water - Building Works
A11: =A10+1 -> 4 | B11: Rainwater re-use collection and re-use system
A12: =A11+1 -> 5 | B12: Stormwater Plumbing and Drainage
A13: =A12+1 -> 6 | B13: Supply and install OSD tank and associated work
A14: =A13+1 -> 7 | B14: External Underground Cold Water Works Including, Scanning, Trenching, Bedding and Backfill
A15: =A14+1 -> 8 | B15: External Underground Sewer Works Including, Scanning, Trenching, Bedding and Backfill
A16: =A15+1 -> 9 | B16: External Underground Gas Works Including, Scanning, Trenching, Bedding and Backfill
A17: =A16+1 -> 10 | B17: Authority fee requirement including work permits and service connections
A18: =A17+1 -> 11 | B18: Supply and Install of Sanitary Fixtures and Fittings
A19: =A18+1 -> 12 | B19: Other Items, Please Specify
A20: =A19+1 -> 13 | B20: Subtotal - Hydraulics | C20: =SUM(C8:C19) -> 0
A21: =A20+1 -> 14 | B21: Fire Hydrant Protection System
A22: =A21+1 -> 15 | B22: Fire Hose Reel Protection
A23: =A22+1 -> 16 | B23: Connection Charges from Authorities
A24: =A23+1 -> 17 | B24: Other Items, Please Specify
A25: =A24+1 -> 18 | B25: Subtotal - Wet Fire | C25: =SUM(C21:C24) -> 0
A26: =A25+1 -> 19 | B26: Testing and Commissioing
A27: =A26+1 -> 20 | B27: Other Items, Please Specify
A28: =A27+1 -> 21 | B28: Total Hydraulic and Wet Fire Services (Excl. GST) | C28: =C20+C25+C26+C27 -> 0 | D28: Note: this value should equal to the Total of Items 29 and 40-45 in the "Main Works" tab.

Sheet Dry Fire Breakdown
A1: ='Main Works'!A1 -> SINSW08089/25 New Primary School in Calderwood - Tender Schedules 3 - (Lump Sum)
B3: ='Main Works'!B3 -> [Insert]
A5: Dry Fire Services
A7: # | B7: Discipline | C7: Total (Ex. GST)
A8: 1 | B8: Dry Chemical Fire Extinguisher
A9: =A8+1 -> 2 | B9: Smoke Detection System
A10: =A9+1 -> 3 | B10: Occupant Warning System
A11: =A10+1 -> 4 | B11: FIP and associated works
A12: =A11+1 -> 5 | B12: External Underground Works Including, Scanning, Trenching, Bedding and Backfill (if any)
A13: =A12+1 -> 6 | B13: Design Finalisation
A14: =A13+1 -> 7 | B14: Testing and Commissioing
A15: =A14+1 -> 8 | B15: Other Items, Please Specify
A16: =A15+1 -> 9 | B16: Total Dry Fire Services (Excl. GST) | C16: =SUM(C8:C15) -> 0 | D16: Note: this value should match Item 30 in the "Main Works" tab.

Sheet SOR
A1: SINSW08089-25 New Primary School in Calderwood - Contract Schedule
C3: =' Summary'!C3 -> [Insert]
B5: ='[12]3.3 Delivery Consultants'!B6 -> MAIN WORKS
B6: 3.4 - SCHEDULE OF RATES - ONLY FOR FUTURE VARIATION ASSESSMENT (NOT PART OF THE LUMP SUM PRICE)
B8: Item | C8: Description | D8: Unit | E8: Rate ($)
B9: A | C9: SCHEDULE OF RATES
C10: Complete this Schedule by inserting rates and prices, where appropriate.
C11: The rates and prices tendered will form part of the Contract. The Tenderer must include rates and prices for all items below which are anticipated to be involved in carrying out the Works. It is acknowledged by the Tenderer that any rates or amounts set out below include both off-site overheads and profit and non-time related on-site overheads. These rates and prices setout below may be used by the Principal to assess the tenderers and may be used for any future variations.
C12: The Principal reserves the right to request future variations based on the rates and prices or based on a lump sum price due to economies of scale.
C13: All rates and prices must exclude GST
B15: 1 | C15: EARTHWORKS
B16: =B15+0.01 -> 1.01 | C16: Excavate and stockpile OTR | D16: m3 | E16: 0
B17: =B16+0.01 -> 1.02 | C17: Extra over for rock | D17: m3 | E17: 0
B18: =B17+0.01 -> 1.03 | C18: Excavate, Transport and Dispose of Excavated Natural Material off-site (ENM) | D18: t | E18: 0
B19: =B18+0.01 -> 1.04 | C19: Excavate, Transport and Dispose of Virgin Excavated Natural Material off-site (VENM) | D19: t | E19: 0
B20: =B19+0.01 -> 1.05 | C20: Excavate, Transport and Dispose of General Solid Waste (Putrescible) off-site (GSW) | D20: t | E20: 0
B21: =B20+0.01 -> 1.06 | C21: Excavate, Transport and Dispose of General Solid Waste (Non-Putrescible) off-site (GSW) | D21: t | E21: 0
B22: =B21+0.01 -> 1.07 | C22: Excavate, Transport and Dispose of General Solid Waste (Recyclable) off-site (GSW) | D22: t | E22: 0
B23: =B22+0.01 -> 1.08 | C23: Excavate, Transport and Dispose of Restricted Solid Waste off-site | D23: t | E23: 0
B24: =B23+0.01 -> 1.09 | C24: Excavate, Transport and Dispose of Asbestos contaminated soils off-site | D24: t | E24: 0
B25: =B24+0.01 -> 1.1 | C25: Excavate, Transport and Dispose of Hazardous and unsuitable material off-site | D25: t | E25: 0
B26: =B25+0.01 -> 1.11 | C26: Excavate, Transport and Dispose of Restricted Solid Waste (Non-Putrescible) - Building & Demolition waste off-site | D26: t | E26: 0
B27: =B26+0.01 -> 1.12 | C27: Pump out, storage, transport and disposal of contaminated Liquid Waste (incl EPA levied facility fees) | D27: m3 | E27: 0
B28: =B27+0.01 -> 1.13 | C28: Imported engineered fill material | D28: t | E28: 0
B29: 2 | C29: ASBESTOS MANAGEMENT RATES (Hazardous Materials)
B30: =B29+0.01 -> 2.01 | C30: Clearance Certificates | D30: No | E30: 0
B31: =B30+0.01 -> 2.02 | C31: Decontamination Unit Hire | D31: Day | E31: 0
B32: =B31+0.01 -> 2.03 | C32: Asbestos Air Monitors (per day, each) | D32: Day | E32: 0
B33: =B32+0.01 -> 2.04 | C33: Asbestos removal works – Asbestos Contaminated Material (ACM) Friable (Rate to incl. overheads and any associated cost for the removal of asbestos.) | D33: t | E33: 0
B34: =B33+0.01 -> 2.05 | C34: Asbestos removal works – Asbestos Contaminated Material (ACM) Non-Friable (Rate to incl. overheads and any associated cost for the removal of asbestos.) | D34: t | E34: 0
B35: =B34+0.01 -> 2.06 | C35: Lead paint removal works (Rate to incl. overheads and any associated cost for the removal of lead) | D35: t | E35: 0
B36: =B35+0.01 -> 2.07 | C36: Certified Occupational Hygienist (per day) | D36: Day | E36: 0
B37: =B36+0.01 -> 2.08 | C37: Occupational Hygienist (per day) | D37: Day | E37: 0
B38: 3 | C38: MONITORING RATES
B39: =B38+0.01 -> 3.01 | C39: Vibration Monitors (per day) | D39: Day | E39: 0
B40: =B39+0.01 -> 3.02 | C40: Dust Monitors (per day) | D40: Day | E40: 0
B41: =B40+0.01 -> 3.03 | C41: Noise Monitors (per day) | D41: Day | E41: 0
B42: =B41+0.01 -> 3.04 | C42: Air Monitors (per day) | D42: Day | E42: 0
B43: 4 | C43: STRUCTURAL TRADES
B44: =B43+0.01 -> 4.01 | C44: Concrete
...

Sheet SoR Labour
A1: =SOR!A1 -> SINSW08089-25 New Primary School in Calderwood - Contract Schedule
C3: =' Summary'!C3 -> [Insert]
B5: ='[12]3.1 Preliminaries'!B6 -> MAIN WORKS
B6: 3.5 - LABOUR RATES - ONLY FOR FUTURE VARIATION ASSESSMENT (NOT PART OF THE LUMP SUM PRICE)
B8: Item | C8: Description | D8: Normal | E8: Time & Half | F8: Double Time
B9: A | C9: SCHEDULE OF RATES
C10: Complete this Schedule by inserting rates and prices, where appropriate.
C11: The rates and prices tendered will form part of the Contract. The Tenderer must include rates and prices for all items below which are anticipated to be involved in carrying out the Works. It is acknowledged by the Tenderer that any rates or amounts set out below include both off-site overheads and profit and non-time related on-site overheads. These rates and prices setout below may be used by the Principal to assess the tenderers and may be used for any future variations.
C12: The Principal reserves the right to request future variations based on the rates and prices or based on a lump sum price due to economies of scale.
C13: All rates and prices must exclude GST
B15: B | C15: LABOUR RATES
B16: 1.01 | C16: Note: All rates to exclude profit/ margin & GST
B17: =B16+0.01 -> 1.02 | C17: Project Director | D17: 0 | E17: 0 | F17: 0
B18: =B17+0.01 -> 1.03 | C18: Construction Manager | D18: 0 | E18: 0 | F18: 0
B19: =B18+0.01 -> 1.04 | C19: Senior Project Manager | D19: 0 | E19: 0 | F19: 0
B20: =B19+0.01 -> 1.05 | C20: Project Manager | D20: 0 | E20: 0 | F20: 0
B21: =B20+0.01 -> 1.06 | C21: Assistant Project Manager | D21: 0 | E21: 0 | F21: 0
B22: =B21+0.01 -> 1.07 | C22: Contract Manager | D22: 0 | E22: 0 | F22: 0
B23: =B22+0.01 -> 1.08 | C23: Commissioning & Operational Readiness Manager | D23: 0 | E23: 0 | F23: 0
B24: =B23+0.01 -> 1.09 | C24: Senior Design Manager | D24: 0 | E24: 0 | F24: 0
B25: =B24+0.01 -> 1.1 | C25: Design Manager | D25: 0 | E25: 0 | F25: 0
B26: =B25+0.01 -> 1.11 | C26: Design Assistant | D26: 0 | E26: 0 | F26: 0
B27: =B26+0.01 -> 1.12 | C27: Design Quality Control Manager | D27: 0 | E27: 0 | F27: 0
B28: =B27+0.01 -> 1.13 | C28: BIM Manager | D28: 0 | E28: 0 | F28: 0
... B93: =B92+0.01 -> 1.78 | C93: Connecting w/ Country Consultant | D93: 0 | E93: 0 | F93: 0

Sheet SoR Equipmt
A1: SINSW08089-25 New Primary School in Calderwood - Contract Schedule
C3: =' Summary'!C3 -> [Insert]
B5: ='[12]3.1 Preliminaries'!B6 -> MAIN WORKS
B6: 3.6 - HIRE RATES INCL LABOUR (where applicable) - ONLY FOR FUTURE VARIATION ASSESSMENT (NOT PART OF THE LUMP SUM PRICE)
B8: Item | C8: Description | D8: Total ($) excl. GST
B9: A | C9: CONTRACTOR'S MANAGEMENT AND SUPERVISION
C10: Complete this Schedule by inserting rates and prices, where appropriate.
C11: The rates and prices tendered will form part of the Contract. The Tenderer must include rates and prices for all items below which are anticipated to be involved in carrying out the Works. It is acknowledged by the Tenderer that any rates or amounts set out below include both off-site overheads and profit and non-time related on-site overheads. These rates and prices setout below may be used by the Principal to assess the tenderers and may be used for any future variations.
C12: The Principal reserves the right to request future variations based on the rates and prices or based on a lump sum price due to economies of scale.
C13: All rates and prices must exclude GST
B15: B | C15: LABOUR RATES | D15: $/day
B16: 1.01 | C16: Note: All rates to include operator and exclude profit/ margin & GST
B17: =B16+0.01 -> 1.02 | C17: 5 tn excavator | D17: 0
B18: =B17+0.01 -> 1.03 | C18: 6 tn excavator | D18: 0
B19: =B18+0.01 -> 1.04 | C19: 8 tn excavator | D19: 0
B20: =B19+0.01 -> 1.05 | C20: 10 tn excavator | D20: 0
B21: =B20+0.01 -> 1.06 | C21: 12 tn excavator | D21: 0
B22: =B21+0.01 -> 1.07 | C22: 14 tn excavator | D22: 0
B23: =B22+0.01 -> 1.08 | C23: 15 tn excavator | D23: 0
B24: =B23+0.01 -> 1.09 | C24: 20 tn excavator | D24: 0
B25: =B24+0.01 -> 1.1 | C25: 26 tn excavator | D25: 0
B26: =B25+0.01 -> 1.11 | C26: 30 tn excavator | D26: 0
B27: =B26+0.01 -> 1.12 | C27: 36T excavator | D27: 0
B28: =B27+0.01 -> 1.13 | C28: 50T excavator | D28: 0
... B57: =B56+0.01 -> 1.42 | C57: Tower Crane | D57: 0
B58: 1.43 | C58: Mobile Crane | D58: 0
B59: 1.44 | C59: Anything else contractor feels is required | D59: 0

Sheet Sheet3
