Workbook
Name BT: 'DATA SHEET'!$B$540:$B$575
Name CHS: 'DATA SHEET'!$B$82:$B$198
Name Column: 'DATA SHEET'!$L$24
Name CT: 'DATA SHEET'!$B$579:$B$594
Name DimFolder: 'DATA SHEET'!$L$3:$M$19
Name EA: 'DATA SHEET'!$B$201:$B$248
Name FB: 'DATA SHEET'!$B$535:$B$537
Name Framing: 'DATA SHEET'!$L$25
Name PFC: 'DATA SHEET'!$B$490:$B$501
Name Purlins_Girths_Bracings: 'DATA SHEET'!$L$27
Name PurlinsxGirthsxBracings: 'DATA SHEET'!$L$16:$L$18
Name RHS: 'DATA SHEET'!$B$274:$B$368
Name Roof: 'DATA SHEET'!$L$26
Name SHS: 'DATA SHEET'!$B$386:$B$487
Name SteelType: Table27[Steel Type]
Name UA: 'DATA SHEET'!$B$251:$B$271
Name UB: 'DATA SHEET'!$B$3:$B$53
Name UC: 'DATA SHEET'!$B$56:$B$78
Name WB: 'DATA SHEET'!$B$504:$B$532
Name WC: 'DATA SHEET'!$B$597:$B$616

Sheet READ FIRST!!
A2: INSTRUCTIONS IN USING THIS FORMAT
A3: 1 | B3: Fill up cells highlighted in yellow only. As much as possible do not edit cells with formulas
B4: 1.a | C4: TAG/MARK - manually type the tagging based from plans
B5: 1.b | C5: STEEL TYPE & STEEL SECTION - a drop down list is provided, please choose corresponding steel types and section for given tag/mark
A6: 2 | B6: If steel type/section is not in the list, data is not yet available in the "DATA SHEET" tab. A blank row is provided at end of each table for adding another steel section. Please copy first the designated row for new data
A20: 3 | B20: You can navigate in "DATA SHEET" tab with hyperlinked cells

Sheet <PROJECT>
A1: <PROJECT> | K1: !! DO NOT EDIT BEYOND THIS COLUMN !!
A2: TYPE OF MEMBER (Don't leave blank if CSV file will be imported to costX) | B2: TAG/ MARK | C2: STEEL TYPE | D2: STEEL SECTION | E2: DESCRIPTION FOR PURLINS, GIRTHS, BRACINGS AND OTHERS | F2: UNIT WEIGHT | G2: SURFACE PERIMETER | H2: REMARKS/ADDITIONAL DESCRIPTION | I2: FORMAT | J2: Paste as values here for easier copying in costX/Cubit | L2: With number in tagging? | M2: Color Code | N2: Color Code | O2: Dimension Group Folder | P2: Folder* | Q2: Name* | R2: =Table2[[#Headers],[Measurement Type*]] -> Measurement Type* | S2: =Table2[[#Headers],[Default Display]] -> Default Display | T2: Weight Unit | U2: =Table2[[#Headers],[Positive Colour Name]] -> Positive Colour Name | V2: Negative Colour Name | W2: =Table2[[#Headers],[Positive Hatch/Symbol]] -> Positive Hatch/Symbol | X2: Negative Hatch/Symbol | Y2: ='DATA SHEET'!Q23 -> Name Formula Expression (Measured Dimensions) | Z2: ='DATA SHEET'!R23 -> Height Formula Expression (Measured Dimensions) | AA2: ='DATA SHEET'!S23 -> Count Formula Expression (Measured Dimensions) | AB2: ='DATA SHEET'!T23 -> Length Formula Expression (Measured Dimensions) | AC2: Weight Formula XNUMBER POSITION | AD2: Weight Formula Expression (Measured Dimensions) | AE2: Custom 1 Name | AF2: Custom 1 Unit | AG2: Custom 1 Formula XNUMBER position | AH2: Custom 1 Formula Expression (Measured Dimensions) | AI2: Custom 1 Formula Expression (BIM Dimensions) | AJ2: Custom 2 Name | AK2: Custom 2 Unit | AL2: =Table2[[#Headers],[Custom 2 Formula Expression (Measured Dimensions)]] -> Custom 2 Formula Expression (Measured Dimensions) | AM2: Custom 2 Formula Expression (BIM Dimensions) | AN2: Custom 3 Name | AO2: Custom 3 Unit | AP2: =Table2[[#Headers],[Custom 3 Formula Expression (Measured Dimensions)]] -> Custom 3 Formula Expression (Measured Dimensions) | AQ2: Custom 3 Formula Expression (BIM Dimensions)
A3: TEMPLATE | L3: TRUE | M3: {=IFERROR(_xlfn.IFS(R3="Count",RANDBETWEEN(1,COUNTIF($R$11:$R$653,"Count")),R3="Length",RANDBETWEEN(1,COUNTIF($R$11:$R$653,"Length"))),"")} | N3: =IFERROR(_xlfn.RANK.EQ(M3,$M$11:$M$653)+COUNTIF($M3:M$11,M3)-1,"") | O3: Flat Bar | P3: TO DELETE IN COSTX\Do not delete in CSV File | Q3: Do not delete in CSV file, delete when done importing in costX | R3: Count | S3: Weight | T3: t | U3: Orange | V3: Red | W3: Crosshairs | X3: Crosshairs | Y3: "mm high" | Z3: XNUMBER({Dimension Name},1)/1000 | AA3: [Count] | AB3: {Count}*{Height} | AC3: 4 | AD3: {Length}*XNUMBER({Dimension Group Name},4)/1000 | AE3: Steel Surface Area | AF3: m2 | AG3: 5 | AH3: {Length}*XNUMBER({Dimension Group Name},5)/1000
A4: Column | B4: PSC1 | C4: UC | D4: 75x5 Flat Bar | F4: {=IF(COUNT(FIND(PurlinsxGirthsxBracings,$C4))>0,0,ROUNDUP(IF(D4=0,0,VLOOKUP(D4,'DATA SHEET'!$B:$D,2,FALSE)),2))} -> 2.95 | G4: {=IF(COUNT(FIND(PurlinsxGirthsxBracings,$C4))>0,0,ROUNDUP(IF(D4=0,0,VLOOKUP(D4,'DATA SHEET'!$B:$D,3,FALSE)),2))} -> 160 | I4: {=IF(AND(ISBLANK(B4),ISBLANK(C4),ISBLANK(E4)),0,IF(COUNT(FIND(PurlinsxGirthsxBracings,$C4))>0,IF(B4=0,CONCATENATE(E4," ",C4),CONCATENATE(B4," - ",E4," ",C4)),IF(B4=0,IF(ISBLANK(C4),E4,CONCATENATE(D4,", ",F4,"kg/m, ",G4,"mm surface perimeter")),IF(AND(ISBLANK(C4),ISTEXT(E4)),CONCATENATE(B4," - ",E4),IF(AND(ISBLANK(C4),ISBLANK(E4)),B4,CONCATENATE(B4," - ",D4,", ",F4,"kg/m, ",G4,"mm surface perimeter"))))&IF(ISBLANK(H4),"",H4)))} -> PSC1 - 75x5 Flat Bar, 2.95kg/m, 160mm surface perimeter | L4: {=IF(COUNT(FIND({0,1,2,3,4,5,6,7,8,9},B4))>0,COUNT(FIND({0,1,2,3,4,5,6,7,8,9},B4))>0,"")} -> TRUE | M4: {=IFERROR(_xlfn.IFS(R4="Count",RANDBETWEEN(1,COUNTIF($R$11:$R$653,"Count")),R4="Length",RANDBETWEEN(1,COUNTIF($R$11:$R$653,"Length"))),"")} | N4: =IFERROR(_xlfn.RANK.EQ(M4,$M$11:$M$653)+COUNTIF($M4:M$11,M4)-1,"") | O4: =IF(A4='DATA SHEET'!$L$36,C4,IFERROR(IF(AND(ISTEXT(I4),ISBLANK(C4)),"No details",VLOOKUP(C4,DimFolder,2,FALSE)),"")) -> CHS, UB, UC, WB, WC, BT, CT | P4: =IF(AND(ISBLANK(B4),ISBLANK(C4)),"",CONCATENATE("Structural\Structural Steel\",A4,"\",O4)) -> Structural\Structural Steel\Column\CHS, UB, UC, WB, WC, BT, CT | Q4: =IF(AND(ISBLANK(B4),ISBLANK(C4)),"",I4) -> PSC1 - 75x5 Flat Bar, 2.95kg/m, 160mm surface perimeter | R4: {=IF(INDEX(Table2[],_xlfn.XMATCH($A4,Table2[Steel Member],0),_xlfn.XMATCH(R$2,Table2[#Headers],0))=0,"",INDEX(Table2[],_xlfn.XMATCH($A4,Table2[Steel Member],0),_xlfn.XMATCH(R$2,Table2[#Headers],0)))} -> Count | S4: {=IF(INDEX(Table2[],_xlfn.XMATCH($A4,Table2[Steel Member],0),_xlfn.XMATCH(S$2,Table2[#Headers],0))=0,"",INDEX(Table2[],_xlfn.XMATCH($A4,Table2[Steel Member],0),_xlfn.XMATCH(S$2,Table2[#Headers],0)))} -> Weight | T4: =IF(AND(ISBLANK(B4),ISBLANK(C4)),"","t") -> t | U4: {=IF(INDEX(Table2[],_xlfn.XMATCH($A4,Table2[Steel Member],0),_xlfn.XMATCH(U$2,Table2[#Headers],0))=0,"",INDEX(Table2[],_xlfn.XMATCH($A4,Table2[Steel Member],0),_xlfn.XMATCH(U$2,Table2[#Headers],0)))} -> Orange | V4: =IF(AND(ISBLANK(B4),ISBLANK(C4)),"","Red") -> Red | W4: {=IF(INDEX(Table2[],_xlfn.XMATCH($A4,Table2[Steel Member],0),_xlfn.XMATCH(W$2,Table2[#Headers],0))=0,"",INDEX(Table2[],_xlfn.XMATCH($A4,Table2[Steel Member],0),_xlfn.XMATCH(W$2,Table2[#Headers],0)))} -> Crosshairs | X4: =W4 -> Crosshairs | Y4: {=IF(INDEX(Table2[],_xlfn.XMATCH($A4,Table2[Steel Member],0),_xlfn.XMATCH(Y$2,Table2[#Headers],0))=0,"",INDEX(Table2[],_xlfn.XMATCH($A4,Table2[Steel Member],0),_xlfn.XMATCH(Y$2,Table2[#Headers],0)))} -> "mm high" | Z4: {=IF(INDEX(Table2[],_xlfn.XMATCH($A4,Table2[Steel Member],0),_xlfn.XMATCH(Z$2,Table2[#Headers],0))=0,"",INDEX(Table2[],_xlfn.XMATCH($A4,Table2[Steel Member],0),_xlfn.XMATCH(Z$2,Table2[#Headers],0)))} -> XNUMBER({Dimension Name},1)/1000 | AA4: {=IF(INDEX(Table2[],_xlfn.XMATCH($A4,Table2[Steel Member],0),_xlfn.XMATCH(AA$2,Table2[#Headers],0))=0,"",INDEX(Table2[],_xlfn.XMATCH($A4,Table2[Steel Member],0),_xlfn.XMATCH(AA$2,Table2[#Headers],0)))} -> [Count] | AB4: {=IF(INDEX(Table2[],_xlfn.XMATCH($A4,Table2[Steel Member],0),_xlfn.XMATCH(AB$2,Table2[#Headers],0))=0,"",INDEX(Table2[],_xlfn.XMATCH($A4,Table2[Steel Member],0),_xlfn.XMATCH(AB$2,Table2[#Headers],0)))} -> {Count}*{Height} | AC4: {=IFERROR(INDEX(Table8[],_xlfn.XMATCH($O4,Table8[Dimension Name Category],0),_xlfn.XMATCH(AC$2&IF($L4," w/ tag"," w/o tag"),Table8[#Headers],0)),"")} -> 4 | AD4: =IF(OR($AC4="",$AC4=0),"",IF($A4=Column,"{Length}*XNUMBER({Dimension Group Name},"&$AC4&")/1000","{Length}*XNUMBER({Dimension Group Name},"&$AC4&")/1000*{Slope Factor}")) -> {Length}*XNUMBER({Dimension Group Name},4)/1000 | AE4: =IF(AND(ISBLANK(B4),ISBLANK(C4)),"",IF($A4=Purlins_Girths_Bracings,"","Steel Surface Area")) -> Steel Surface Area | AF4: =IF(AND(ISBLANK(B4),ISBLANK(C4)),"",IF($A4=Purlins_Girths_Bracings,"","m2")) -> m2 | AG4: {=IFERROR(INDEX(Table8[],_xlfn.XMATCH($O4,Table8[Dimension Name Category],0),_xlfn.XMATCH(AG$2&IF($L4," w/ tag"," w/o tag"),Table8[#Headers],0)),"")} -> 5 | AH4: =IF(OR($AG4="",$AG4=0),"",IF($A4=Column,"{Length}*XNUMBER({Dimension Group Name},"&$AG4&")/1000","{Length}*XNUMBER({Dimension Group Name},"&$AG4&")/1000*{Slope Factor}")) -> {Length}*XNUMBER({Dimension Group Name},5)/1000 | AJ4: =IF(OR($A4=Column,$A4=""),"","Slope Length") | AK4: =IF(OR($A4=Column,$A4=""),"","m") | AL4: {=IF(INDEX(Table2[],_xlfn.XMATCH($A4,Table2[Steel Member],0),_xlfn.XMATCH(AL$2,Table2[#Headers],0))=0,"",INDEX(Table2[],_xlfn.XMATCH($A4,Table2[Steel Member],0),_xlfn.XMATCH(AL$2,Table2[#Headers],0)))} | AN4: =IF(OR($A4=Column,$A4=""),"","Slope Factor") | AP4: {=IF(INDEX(Table2[],_xlfn.XMATCH($A4,Table2[Steel Member],0),_xlfn.XMATCH(AP$2,Table2[#Headers],0))=0,"",INDEX(Table2[],_xlfn.XMATCH($A4,Table2[Steel Member],0),_xlfn.XMATCH(AP$2,Table2[#Headers],0)))}
A5: Framing | C5: UB | D5: 102x76x5RHS | F5: {=IF(COUNT(FIND(PurlinsxGirthsxBracings,$C5))>0,0,ROUNDUP(IF(D5=0,0,VLOOKUP(D5,'DATA SHEET'!$B:$D,2,FALSE)),2))} -> 12.5 | G5: {=IF(COUNT(FIND(PurlinsxGirthsxBracings,$C5))>0,0,ROUNDUP(IF(D5=0,0,VLOOKUP(D5,'DATA SHEET'!$B:$D,3,FALSE)),2))} -> 356 | I5: {=IF(AND(ISBLANK(B5),ISBLANK(C5),ISBLANK(E5)),0,IF(COUNT(FIND(PurlinsxGirthsxBracings,$C5))>0,IF(B5=0,CONCATENATE(E5," ",C5),CONCATENATE(B5," - ",E5," ",C5)),IF(B5=0,IF(ISBLANK(C5),E5,CONCATENATE(D5,", ",F5,"kg/m, ",G5,"mm surface perimeter")),IF(AND(ISBLANK(C5),ISTEXT(E5)),CONCATENATE(B5," - ",E5),IF(AND(ISBLANK(C5),ISBLANK(E5)),B5,CONCATENATE(B5," - ",D5,", ",F5,"kg/m, ",G5,"mm surface perimeter"))))&IF(ISBLANK(H5),"",H5)))} -> 102x76x5RHS, 12.5kg/m, 356mm surface perimeter | L5: {=IF(COUNT(FIND({0,1,2,3,4,5,6,7,8,9},B5))>0,COUNT(FIND({0,1,2,3,4,5,6,7,8,9},B5))>0,"")} | M5: {=IFERROR(_xlfn.IFS(R5="Count",RANDBETWEEN(1,COUNTIF($R$11:$R$653,"Count")),R5="Length",RANDBETWEEN(1,COUNTIF($R$11:$R$653,"Length"))),"")} -> 2 | N5: =IFERROR(_xlfn.RANK.EQ(M5,$M$11:$M$653)+COUNTIF($M5:M$11,M5)-1,"") -> 13 | O5: =IF(A5='DATA SHEET'!$L$36,C5,IFERROR(IF(AND(ISTEXT(I5),ISBLANK(C5)),"No details",VLOOKUP(C5,DimFolder,2,FALSE)),"")) -> CHS, UB, UC, WB, WC, BT, CT | P5: =IF(AND(ISBLANK(B5),ISBLANK(C5)),"",CONCATENATE("Structural\Structural Steel\",A5,"\",O5)) -> Structural\Structural Steel\Framing\CHS, UB, UC, WB, WC, BT, CT | Q5: =IF(AND(ISBLANK(B5),ISBLANK(C5)),"",I5) -> 102x76x5RHS, 12.5kg/m, 356mm surface perimeter | R5: {=IF(INDEX(Table2[],_xlfn.XMATCH($A5,Table2[Steel Member],0),_xlfn.XMATCH(R$2,Table2[#Headers],0))=0,"",INDEX(Table2[],_xlfn.XMATCH($A5,Table2[Steel Member],0),_xlfn.XMATCH(R$2,Table2[#Headers],0)))} -> Length | S5: {=IF(INDEX(Table2[],_xlfn.XMATCH($A5,Table2[Steel Member],0),_xlfn.XMATCH(S$2,Table2[#Headers],0))=0,"",INDEX(Table2[],_xlfn.XMATCH($A5,Table2[Steel Member],0),_xlfn.XMATCH(S$2,Table2[#Headers],0)))} -> Weight | T5: =IF(AND(ISBLANK(B5),ISBLANK(C5)),"","t") -> t | U5: {=IF(INDEX(Table2[],_xlfn.XMATCH($A5,Table2[Steel Member],0),_xlfn.XMATCH(U$2,Table2[#Headers],0))=0,"",INDEX(Table2[],_xlfn.XMATCH($A5,Table2[Steel Member],0),_xlfn.XMATCH(U$2,Table2[#Headers],0)))} -> Blue | V5: =IF(AND(ISBLANK(B5),ISBLANK(C5)),"","Red") -> Red | W5: {=IF(INDEX(Table2[],_xlfn.XMATCH($A5,Table2[Steel Member],0),_xlfn.XMATCH(W$2,Table2[#Headers],0))=0,"",INDEX(Table2[],_xlfn.XMATCH($A5,Table2[Steel Member],0),_xlfn.XMATCH(W$2,Table2[#Headers],0)))} | X5: =W5 | Y5: {=IF(INDEX(Table2[],_xlfn.XMATCH($A5,Table2[Steel Member],0),_xlfn.XMATCH(Y$2,Table2[#Headers],0))=0,"",INDEX(Table2[],_xlfn.XMATCH($A5,Table2[Steel Member],0),_xlfn.XMATCH(Y$2,Table2[#Headers],0)))} -> "0 degrees" | Z5: {=IF(INDEX(Table2[],_xlfn.XMATCH($A5,Table2[Steel Member],0),_xlfn.XMATCH(Z$2,Table2[#Headers],0))=0,"",INDEX(Table2[],_xlfn.XMATCH($A5,Table2[Steel Member],0),_xlfn.XMATCH(Z$2,Table2[#Headers],0)))} | AA5: {=IF(INDEX(Table2[],_xlfn.XMATCH($A5,Table2[Steel Member],0),_xlfn.XMATCH(AA$2,Table2[#Headers],0))=0,"",INDEX(Table2[],_xlfn.XMATCH($A5,Table2[Steel Member],0),_xlfn.XMATCH(AA$2,Table2[#Headers],0)))} -> [Count] | AB5: {=IF(INDEX(Table2[],_xlfn.XMATCH($A5,Table2[Steel Member],0),_xlfn.XMATCH(AB$2,Table2[#Headers],0))=0,"",INDEX(Table2[],_xlfn.XMATCH($A5,Table2[Steel Member],0),_xlfn.XMATCH(AB$2,Table2[#Headers],0)))} -> [Length] | AC5: {=IFERROR(INDEX(Table8[],_xlfn.XMATCH($O5,Table8[Dimension Name Category],0),_xlfn.XMATCH(AC$2&IF($L5," w/ tag"," w/o tag"),Table8[#Headers],0)),"")} | AD5: =IF(OR($AC5="",$AC5=0),"",IF($A5=Column,"{Length}*XNUMBER({Dimension Group Name},"&$AC5&")/1000","{Length}*XNUMBER({Dimension Group Name},"&$AC5&")/1000*{Slope Factor}")) | AE5: =IF(AND(ISBLANK(B5),ISBLANK(C5)),"",IF($A5=Purlins_Girths_Bracings,"","Steel Surface Area")) -> Steel Surface Area | AF5: =IF(AND(ISBLANK(B5),ISBLANK(C5)),"",IF($A5=Purlins_Girths_Bracings,"","m2")) -> m2 | AG5: {=IFERROR(INDEX(Table8[],_xlfn.XMATCH($O5,Table8[Dimension Name Category],0),_xlfn.XMATCH(AG$2&IF($L5," w/ tag"," w/o tag"),Table8[#Headers],0)),"")} | AH5: =IF(OR($AG5="",$AG5=0),"",IF($A5=Column,"{Length}*XNUMBER({Dimension Group Name},"&$AG5&")/1000","{Length}*XNUMBER({Dimension Group Name},"&$AG5&")/1000*{Slope Factor}")) | AJ5: =IF(OR($A5=Column,$A5=""),"","Slope Length") -> Slope Length | AK5: =IF(OR($A5=Column,$A5=""),"","m") -> m | AL5: {=IF(INDEX(Table2[],_xlfn.XMATCH($A5,Table2[Steel Member],0),_xlfn.XMATCH(AL$2,Table2[#Headers],0))=0,"",INDEX(Table2[],_xlfn.XMATCH($A5,Table2[Steel Member],0),_xlfn.XMATCH(AL$2,Table2[#Headers],0)))} -> [Length]*{Slope Factor} | AN5: =IF(OR($A5=Column,$A5=""),"","Slope Factor") -> Slope Factor | AP5: {=IF(INDEX(Table2[],_xlfn.XMATCH($A5,Table2[Steel Member],0),_xlfn.XMATCH(AP$2,Table2[#Headers],0))=0,"",INDEX(Table2[],_xlfn.XMATCH($A5,Table2[Steel Member],0),_xlfn.XMATCH(AP$2,Table2[#Headers],0)))} -> 1/COS(RADIANS(XNUMBER({Dimension Name},1)))
A6: Purlins, Girts and Bracings | C6: Bracings | E6: 20mm dia. Rod | F6: {=IF(COUNT(FIND(PurlinsxGirthsxBracings,$C6))>0,0,ROUNDUP(IF(D6=0,0,VLOOKUP(D6,'DATA SHEET'!$B:$D,2,FALSE)),2))} -> 0 | G6: {=IF(COUNT(FIND(PurlinsxGirthsxBracings,$C6))>0,0,ROUNDUP(IF(D6=0,0,VLOOKUP(D6,'DATA SHEET'!$B:$D,3,FALSE)),2))} -> 0 | I6: {=IF(AND(ISBLANK(B6),ISBLANK(C6),ISBLANK(E6)),0,IF(COUNT(FIND(PurlinsxGirthsxBracings,$C6))>0,IF(B6=0,CONCATENATE(E6," ",C6),CONCATENATE(B6," - ",E6," ",C6)),IF(B6=0,IF(ISBLANK(C6),E6,CONCATENATE(D6,", ",F6,"kg/m, ",G6,"mm surface perimeter")),IF(AND(ISBLANK(C6),ISTEXT(E6)),CONCATENATE(B6," - ",E6),IF(AND(ISBLANK(C6),ISBLANK(E6)),B6,CONCATENATE(B6," - ",D6,", ",F6,"kg/m, ",G6,"mm surface perimeter"))))&IF(ISBLANK(H6),"",H6)))} -> 20mm dia. Rod Bracings | L6: {=IF(COUNT(FIND({0,1,2,3,4,5,6,7,8,9},B6))>0,COUNT(FIND({0,1,2,3,4,5,6,7,8,9},B6))>0,"")} | M6: {=IFERROR(_xlfn.IFS(R6="Count",RANDBETWEEN(1,COUNTIF($R$11:$R$653,"Count")),R6="Length",RANDBETWEEN(1,COUNTIF($R$11:$R$653,"Length"))),"")} -> 13 | N6: =IFERROR(_xlfn.RANK.EQ(M6,$M$11:$M$653)+COUNTIF($M6:M$11,M6)-1,"") -> 3 | O6: =IF(A6='DATA SHEET'!$L$36,C6,IFERROR(IF(AND(ISTEXT(I6),ISBLANK(C6)),"No details",VLOOKUP(C6,DimFolder,2,FALSE)),"")) -> Bracings | P6: =IF(AND(ISBLANK(B6),ISBLANK(C6)),"",CONCATENATE("Structural\Structural Steel\",A6,"\",O6)) -> Structural\Structural Steel\Purlins, Girts and Bracings\Bracings | Q6: =IF(AND(ISBLANK(B6),ISBLANK(C6)),"",I6) -> 20mm dia. Rod Bracings | R6: {=IF(INDEX(Table2[],_xlfn.XMATCH($A6,Table2[Steel Member],0),_xlfn.XMATCH(R$2,Table2[#Headers],0))=0,"",INDEX(Table2[],_xlfn.XMATCH($A6,Table2[Steel Member],0),_xlfn.XMATCH(R$2,Table2[#Headers],0)))} -> Length | S6: {=IF(INDEX(Table2[],_xlfn.XMATCH($A6,Table2[Steel Member],0),_xlfn.XMATCH(S$2,Table2[#Headers],0))=0,"",INDEX(Table2[],_xlfn.XMATCH($A6,Table2[Steel Member],0),_xlfn.XMATCH(S$2,Table2[#Headers],0)))} -> Slope Length | T6: =IF(AND(ISBLANK(B6),ISBLANK(C6)),"","t") -> t | U6: {=IF(INDEX(Table2[],_xlfn.XMATCH($A6,Table2[Steel Member],0),_xlfn.XMATCH(U$2,Table2[#Headers],0))=0,"",INDEX(Table2[],_xlfn.XMATCH($A6,Table2[Steel Member],0),_xlfn.XMATCH(U$2,Table2[#Headers],0)))} -> Aqua | V6: =IF(AND(ISBLANK(B6),ISBLANK(C6)),"","Red") -> Red | W6: {=IF(INDEX(Table2[],_xlfn.XMATCH($A6,Table2[Steel Member],0),_xlfn.XMATCH(W$2,Table2[#Headers],0))=0,"",INDEX(Table2[],_xlfn.XMATCH($A6,Table2[Steel Member],0),_xlfn.XMATCH(W$2,Table2[#Headers],0)))} | X6: =W6 | Y6: {=IF(INDEX(Table2[],_xlfn.XMATCH($A6,Table2[Steel Member],0),_xlfn.XMATCH(Y$2,Table2[#Headers],0))=0,"",INDEX(Table2[],_xlfn.XMATCH($A6,Table2[Steel Member],0),_xlfn.XMATCH(Y$2,Table2[#Headers],0)))} -> "0 degrees" | Z6: {=IF(INDEX(Table2[],_xlfn.XMATCH($A6,Table2[Steel Member],0),_xlfn.XMATCH(Z$2,Table2[#Headers],0))=0,"",INDEX(Table2[],_xlfn.XMATCH($A6,Table2[Steel Member],0),_xlfn.XMATCH(Z$2,Table2[#Headers],0)))} | AA6: {=IF(INDEX(Table2[],_xlfn.XMATCH($A6,Table2[Steel Member],0),_xlfn.XMATCH(AA$2,Table2[#Headers],0))=0,"",INDEX(Table2[],_xlfn.XMATCH($A6,Table2[Steel Member],0),_xlfn.XMATCH(AA$2,Table2[#Headers],0)))} -> [Count] | AB6: {=IF(INDEX(Table2[],_xlfn.XMATCH($A6,Table2[Steel Member],0),_xlfn.XMATCH(AB$2,Table2[#Headers],0))=0,"",INDEX(Table2[],_xlfn.XMATCH($A6,Table2[Steel Member],0),_xlfn.XMATCH(AB$2,Table2[#Headers],0)))} -> [Length] | AC6: {=IFERROR(INDEX(Table8[],_xlfn.XMATCH($O6,Table8[Dimension Name Category],0),_xlfn.XMATCH(AC$2&IF($L6," w/ tag"," w/o tag"),Table8[#Headers],0)),"")} | AD6: =IF(OR($AC6="",$AC6=0),"",IF($A6=Column,"{Length}*XNUMBER({Dimension Group Name},"&$AC6&")/1000","{Length}*XNUMBER({Dimension Group Name},"&$AC6&")/1000*{Slope Factor}")) | AE6: =IF(AND(ISBLANK(B6),ISBLANK(C6)),"",IF($A6=Purlins_Girths_Bracings,"","Steel Surface Area")) | AF6: =IF(AND(ISBLANK(B6),ISBLANK(C6)),"",IF($A6=Purlins_Girths_Bracings,"","m2")) | AG6: {=IFERROR(INDEX(Table8[],_xlfn.XMATCH($O6,Table8[Dimension Name Category],0),_xlfn.XMATCH(AG$2&IF($L6," w/ tag"," w/o tag"),Table8[#Headers],0)),"")} | AH6: =IF(OR($AG6="",$AG6=0),"",IF($A6=Column,"{Length}*XNUMBER({Dimension Group Name},"&$AG6&")/1000","{Length}*XNUMBER({Dimension Group Name},"&$AG6&")/1000*{Slope Factor}")) | AJ6: =IF(OR($A6=Column,$A6=""),"","Slope Length") -> Slope Length | AK6: =IF(OR($A6=Column,$A6=""),"","m") -> m | AL6: {=IF(INDEX(Table2[],_xlfn.XMATCH($A6,Table2[Steel Member],0),_xlfn.XMATCH(AL$2,Table2[#Headers],0))=0,"",INDEX(Table2[],_xlfn.XMATCH($A6,Table2[Steel Member],0),_xlfn.XMATCH(AL$2,Table2[#Headers],0)))} -> [Length]*{Slope Factor} | AN6: =IF(OR($A6=Column,$A6=""),"","Slope Factor") -> Slope Factor | AP6: {=IF(INDEX(Table2[],_xlfn.XMATCH($A6,Table2[Steel Member],0),_xlfn.XMATCH(AP$2,Table2[#Headers],0))=0,"",INDEX(Table2[],_xlfn.XMATCH($A6,Table2[Steel Member],0),_xlfn.XMATCH(AP$2,Table2[#Headers],0)))} -> 1/COS(RADIANS(XNUMBER({Dimension Name},1)))
F7: {=IF(COUNT(FIND(PurlinsxGirthsxBracings,$C7))>0,0,ROUNDUP(IF(D7=0,0,VLOOKUP(D7,'DATA SHEET'!$B:$D,2,FALSE)),2))} -> 0 | G7: {=IF(COUNT(FIND(PurlinsxGirthsxBracings,$C7))>0,0,ROUNDUP(IF(D7=0,0,VLOOKUP(D7,'DATA SHEET'!$B:$D,3,FALSE)),2))} -> 0 | I7: {=IF(AND(ISBLANK(B7),ISBLANK(C7),ISBLANK(E7)),0,IF(COUNT(FIND(PurlinsxGirthsxBracings,$C7))>0,IF(B7=0,CONCATENATE(E7," ",C7),CONCATENATE(B7," - ",E7," ",C7)),IF(B7=0,IF(ISBLANK(C7),E7,CONCATENATE(D7,", ",F7,"kg/m, ",G7,"mm surface perimeter")),IF(AND(ISBLANK(C7),ISTEXT(E7)),CONCATENATE(B7," - ",E7),IF(AND(ISBLANK(C7),ISBLANK(E7)),B7,CONCATENATE(B7," - ",D7,", ",F7,"kg/m, ",G7,"mm surface perimeter"))))&IF(ISBLANK(H7),"",H7)))} -> 0 | L7: {=IF(COUNT(FIND({0,1,2,3,4,5,6,7,8,9},B7))>0,COUNT(FIND({0,1,2,3,4,5,6,7,8,9},B7))>0,"")} | M7: {=IFERROR(_xlfn.IFS(R7="Count",RANDBETWEEN(1,COUNTIF($R$11:$R$653,"Count")),R7="Length",RANDBETWEEN(1,COUNTIF($R$11:$R$653,"Length"))),"")} | N7: =IFERROR(_xlfn.RANK.EQ(M7,$M$11:$M$653)+COUNTIF($M7:M$11,M7)-1,"") | O7: =IF(A7='DATA SHEET'!$L$36,C7,IFERROR(IF(AND(ISTEXT(I7),ISBLANK(C7)),"No details",VLOOKUP(C7,DimFolder,2,FALSE)),"")) | P7: =IF(AND(ISBLANK(B7),ISBLANK(C7)),"",CONCATENATE("Structural\Structural Steel\",A7,"\",O7)) | Q7: =IF(AND(ISBLANK(B7),ISBLANK(C7)),"",I7) | R7: {=IF(INDEX(Table2[],_xlfn.XMATCH($A7,Table2[Steel Member],0),_xlfn.XMATCH(R$2,Table2[#Headers],0))=0,"",INDEX(Table2[],_xlfn.XMATCH($A7,Table2[Steel Member],0),_xlfn.XMATCH(R$2,Table2[#Headers],0)))} -> #N/A | S7: {=IF(INDEX(Table2[],_xlfn.XMATCH($A7,Table2[Steel Member],0),_xlfn.XMATCH(S$2,Table2[#Headers],0))=0,"",INDEX(Table2[],_xlfn.XMATCH($A7,Table2[Steel Member],0),_xlfn.XMATCH(S$2,Table2[#Headers],0)))} -> #N/A | T7: =IF(AND(ISBLANK(B7),ISBLANK(C7)),"","t") | U7: {=IF(INDEX(Table2[],_xlfn.XMATCH($A7,Table2[Steel Member],0),_xlfn.XMATCH(U$2,Table2[#Headers],0))=0,"",INDEX(Table2[],_xlfn.XMATCH($A7,Table2[Steel Member],0),_xlfn.XMATCH(U$2,Table2[#Headers],0)))} -> #N/A | V7: =IF(AND(ISBLANK(B7),ISBLANK(C7)),"","Red") | W7: {=IF(INDEX(Table2[],_xlfn.XMATCH($A7,Table2[Steel Member],0),_xlfn.XMATCH(W$2,Table2[#Headers],0))=0,"",INDEX(Table2[],_xlfn.XMATCH($A7,Table2[Steel Member],0),_xlfn.XMATCH(W$2,Table2[#Headers],0)))} -> #N/A | X7: =W7 -> #N/A | Y7: {=IF(INDEX(Table2[],_xlfn.XMATCH($A7,Table2[Steel Member],0),_xlfn.XMATCH(Y$2,Table2[#Headers],0))=0,"",INDEX(Table2[],_xlfn.XMATCH($A7,Table2[Steel Member],0),_xlfn.XMATCH(Y$2,Table2[#Headers],0)))} -> #N/A | Z7: {=IF(INDEX(Table2[],_xlfn.XMATCH($A7,Table2[Steel Member],0),_xlfn.XMATCH(Z$2,Table2[#Headers],0))=0,"",INDEX(Table2[],_xlfn.XMATCH($A7,Table2[Steel Member],0),_xlfn.XMATCH(Z$2,Table2[#Headers],0)))} -> #N/A | AA7: {=IF(INDEX(Table2[],_xlfn.XMATCH($A7,Table2[Steel Member],0),_xlfn.XMATCH(AA$2,Table2[#Headers],0))=0,"",INDEX(Table2[],_xlfn.XMATCH($A7,Table2[Steel Member],0),_xlfn.XMATCH(AA$2,Table2[#Headers],0)))} -> #N/A | AB7: {=IF(INDEX(Table2[],_xlfn.XMATCH($A7,Table2[Steel Member],0),_xlfn.XMATCH(AB$2,Table2[#Headers],0))=0,"",INDEX(Table2[],_xlfn.XMATCH($A7,Table2[Steel Member],0),_xlfn.XMATCH(AB$2,Table2[#Headers],0)))} -> #N/A | AC7: {=IFERROR(INDEX(Table8[],_xlfn.XMATCH($O7,Table8[Dimension Name Category],0),_xlfn.XMATCH(AC$2&IF($L7," w/ tag"," w/o tag"),Table8[#Headers],0)),"")} | AD7: =IF(OR($AC7="",$AC7=0),"",IF($A7=Column,"{Length}*XNUMBER({Dimension Group Name},"&$AC7&")/1000","{Length}*XNUMBER({Dimension Group Name},"&$AC7&")/1000*{Slope Factor}")) | AE7: =IF(AND(ISBLANK(B7),ISBLANK(C7)),"",IF($A7=Purlins_Girths_Bracings,"","Steel Surface Area")) | AF7: =IF(AND(ISBLANK(B7),ISBLANK(C7)),"",IF($A7=Purlins_Girths_Bracings,"","m2")) | AG7: {=IFERROR(INDEX(Table8[],_xlfn.XMATCH($O7,Table8[Dimension Name Category],0),_xlfn.XMATCH(AG$2&IF($L7," w/ tag"," w/o tag"),Table8[#Headers],0)),"")} | AH7: =IF(OR($AG7="",$AG7=0),"",IF($A7=Column,"{Length}*XNUMBER({Dimension Group Name},"&$AG7&")/1000","{Length}*XNUMBER({Dimension Group Name},"&$AG7&")/1000*{Slope Factor}")) | AJ7: =IF(OR($A7=Column,$A7=""),"","Slope Length") | AK7: =IF(OR($A7=Column,$A7=""),"","m") | AL7: {=IF(INDEX(Table2[],_xlfn.XMATCH($A7,Table2[Steel Member],0),_xlfn.XMATCH(AL$2,Table2[#Headers],0))=0,"",INDEX(Table2[],_xlfn.XMATCH($A7,Table2[Steel Member],0),_xlfn.XMATCH(AL$2,Table2[#Headers],0)))} -> #N/A | AN7: =IF(OR($A7=Column,$A7=""),"","Slope Factor") | AP7: {=IF(INDEX(Table2[],_xlfn.XMATCH($A7,Table2[Steel Member],0),_xlfn.XMATCH(AP$2,Table2[#Headers],0))=0,"",INDEX(Table2[],_xlfn.XMATCH($A7,Table2[Steel Member],0),_xlfn.XMATCH(AP$2,Table2[#Headers],0)))} -> #N/A
F8: {=IF(COUNT(FIND(PurlinsxGirthsxBracings,$C8))>0,0,ROUNDUP(IF(D8=0,0,VLOOKUP(D8,'DATA SHEET'!$B:$D,2,FALSE)),2))} -> 0 | G8: {=IF(COUNT(FIND(PurlinsxGirthsxBracings,$C8))>0,0,ROUNDUP(IF(D8=0,0,VLOOKUP(D8,'DATA SHEET'!$B:$D,3,FALSE)),2))} -> 0 | I8: {=IF(AND(ISBLANK(B8),ISBLANK(C8),ISBLANK(E8)),0,IF(COUNT(FIND(PurlinsxGirthsxBracings,$C8))>0,IF(B8=0,CONCATENATE(E8," ",C8),CONCATENATE(B8," - ",E8," ",C8)),IF(B8=0,IF(ISBLANK(C8),E8,CONCATENATE(D8,", ",F8,"kg/m, ",G8,"mm surface perimeter")),IF(AND(ISBLANK(C8),ISTEXT(E8)),CONCATENATE(B8," - ",E8),IF(AND(ISBLANK(C8),ISBLANK(E8)),B8,CONCATENATE(B8," - ",D8,", ",F8,"kg/m, ",G8,"mm surface perimeter"))))&IF(ISBLANK(H8),"",H8)))} -> 0 | L8: {=IF(COUNT(FIND({0,1,2,3,4,5,6,7,8,9},B8))>0,COUNT(FIND({0,1,2,3,4,5,6,7,8,9},B8))>0,"")} | M8: {=IFERROR(_xlfn.IFS(R8="Count",RANDBETWEEN(1,COUNTIF($R$11:$R$653,"Count")),R8="Length",RANDBETWEEN(1,COUNTIF($R$11:$R$653,"Length"))),"")} | N8: =IFERROR(_xlfn.RANK.EQ(M8,$M$11:$M$653)+COUNTIF($M8:M$11,M8)-1,"") | O8: =IF(A8='DATA SHEET'!$L$36,C8,IFERROR(IF(AND(ISTEXT(I8),ISBLANK(C8)),"No details",VLOOKUP(C8,DimFolder,2,FALSE)),"")) | P8: =IF(AND(ISBLANK(B8),ISBLANK(C8)),"",CONCATENATE("Structural\Structural Steel\",A8,"\",O8)) | Q8: =IF(AND(ISBLANK(B8),ISBLANK(C8)),"",I8) | R8: {=IF(INDEX(Table2[],_xlfn.XMATCH($A8,Table2[Steel Member],0),_xlfn.XMATCH(R$2,Table2[#Headers],0))=0,"",INDEX(Table2[],_xlfn.XMATCH($A8,Table2[Steel Member],0),_xlfn.XMATCH(R$2,Table2[#Headers],0)))} -> #N/A | S8: {=IF(INDEX(Table2[],_xlfn.XMATCH($A8,Table2[Steel Member],0),_xlfn.XMATCH(S$2,Table2[#Headers],0))=0,"",INDEX(Table2[],_xlfn.XMATCH($A8,Table2[Steel Member],0),_xlfn.XMATCH(S$2,Table2[#Headers],0)))} -> #N/A | T8: =IF(AND(ISBLANK(B8),ISBLANK(C8)),"","t") | U8: {=IF(INDEX(Table2[],_xlfn.XMATCH($A8,Table2[Steel Member],0),_xlfn.XMATCH(U$2,Table2[#Headers],0))=0,"",INDEX(Table2[],_xlfn.XMATCH($A8,Table2[Steel Member],0),_xlfn.XMATCH(U$2,Table2[#Headers],0)))} -> #N/A | V8: =IF(AND(ISBLANK(B8),ISBLANK(C8)),"","Red") | W8: {=IF(INDEX(Table2[],_xlfn.XMATCH($A8,Table2[Steel Member],0),_xlfn.XMATCH(W$2,Table2[#Headers],0))=0,"",INDEX(Table2[],_xlfn.XMATCH($A8,Table2[Steel Member],0),_xlfn.XMATCH(W$2,Table2[#Headers],0)))} -> #N/A | X8: =W8 -> #N/A | Y8: {=IF(INDEX(Table2[],_xlfn.XMATCH($A8,Table2[Steel Member],0),_xlfn.XMATCH(Y$2,Table2[#Headers],0))=0,"",INDEX(Table2[],_xlfn.XMATCH($A8,Table2[Steel Member],0),_xlfn.XMATCH(Y$2,Table2[#Headers],0)))} -> #N/A | Z8: {=IF(INDEX(Table2[],_xlfn.XMATCH($A8,Table2[Steel Member],0),_xlfn.XMATCH(Z$2,Table2[#Headers],0))=0,"",INDEX(Table2[],_xlfn.XMATCH($A8,Table2[Steel Member],0),_xlfn.XMATCH(Z$2,Table2[#Headers],0)))} -> #N/A | AA8: {=IF(INDEX(Table2[],_xlfn.XMATCH($A8,Table2[Steel Member],0),_xlfn.XMATCH(AA$2,Table2[#Headers],0))=0,"",INDEX(Table2[],_xlfn.XMATCH($A8,Table2[Steel Member],0),_xlfn.XMATCH(AA$2,Table2[#Headers],0)))} -> #N/A | AB8: {=IF(INDEX(Table2[],_xlfn.XMATCH($A8,Table2[Steel Member],0),_xlfn.XMATCH(AB$2,Table2[#Headers],0))=0,"",INDEX(Table2[],_xlfn.XMATCH($A8,Table2[Steel Member],0),_xlfn.XMATCH(AB$2,Table2[#Headers],0)))} -> #N/A | AC8: {=IFERROR(INDEX(Table8[],_xlfn.XMATCH($O8,Table8[Dimension Name Category],0),_xlfn.XMATCH(AC$2&IF($L8," w/ tag"," w/o tag"),Table8[#Headers],0)),"")} | AD8: =IF(OR($AC8="",$AC8=0),"",IF($A8=Column,"{Length}*XNUMBER({Dimension Group Name},"&$AC8&")/1000","{Length}*XNUMBER({Dimension Group Name},"&$AC8&")/1000*{Slope Factor}")) | AE8: =IF(AND(ISBLANK(B8),ISBLANK(C8)),"",IF($A8=Purlins_Girths_Bracings,"","Steel Surface Area")) | AF8: =IF(AND(ISBLANK(B8),ISBLANK(C8)),"",IF($A8=Purlins_Girths_Bracings,"","m2")) | AG8: {=IFERROR(INDEX(Table8[],_xlfn.XMATCH($O8,Table8[Dimension Name Category],0),_xlfn.XMATCH(AG$2&IF($L8," w/ tag"," w/o tag"),Table8[#Headers],0)),"")} | AH8: =IF(OR($AG8="",$AG8=0),"",IF($A8=Column,"{Length}*XNUMBER({Dimension Group Name},"&$AG8&")/1000","{Length}*XNUMBER({Dimension Group Name},"&$AG8&")/1000*{Slope Factor}")) | AJ8: =IF(OR($A8=Column,$A8=""),"","Slope Length") | AK8: =IF(OR($A8=Column,$A8=""),"","m") | AL8: {=IF(INDEX(Table2[],_xlfn.XMATCH($A8,Table2[Steel Member],0),_xlfn.XMATCH(AL$2,Table2[#Headers],0))=0,"",INDEX(Table2[],_xlfn.XMATCH($A8,Table2[Steel Member],0),_xlfn.XMATCH(AL$2,Table2[#Headers],0)))} -> #N/A | AN8: =IF(OR($A8=Column,$A8=""),"","Slope Factor") | AP8: {=IF(INDEX(Table2[],_xlfn.XMATCH($A8,Table2[Steel Member],0),_xlfn.XMATCH(AP$2,Table2[#Headers],0))=0,"",INDEX(Table2[],_xlfn.XMATCH($A8,Table2[Steel Member],0),_xlfn.XMATCH(AP$2,Table2[#Headers],0)))} -> #N/A
F9: {=IF(COUNT(FIND(PurlinsxGirthsxBracings,$C9))>0,0,ROUNDUP(IF(D9=0,0,VLOOKUP(D9,'DATA SHEET'!$B:$D,2,FALSE)),2))} -> 0 | G9: {=IF(COUNT(FIND(PurlinsxGirthsxBracings,$C9))>0,0,ROUNDUP(IF(D9=0,0,VLOOKUP(D9,'DATA SHEET'!$B:$D,3,FALSE)),2))} -> 0 | I9: {=IF(AND(ISBLANK(B9),ISBLANK(C9),ISBLANK(E9)),0,IF(COUNT(FIND(PurlinsxGirthsxBracings,$C9))>0,IF(B9=0,CONCATENATE(E9," ",C9),CONCATENATE(B9," - ",E9," ",C9)),IF(B9=0,IF(ISBLANK(C9),E9,CONCATENATE(D9,", ",F9,"kg/m, ",G9,"mm surface perimeter")),IF(AND(ISBLANK(C9),ISTEXT(E9)),CONCATENATE(B9," - ",E9),IF(AND(ISBLANK(C9),ISBLANK(E9)),B9,CONCATENATE(B9," - ",D9,", ",F9,"kg/m, ",G9,"mm surface perimeter"))))&IF(ISBLANK(H9),"",H9)))} -> 0 | L9: {=IF(COUNT(FIND({0,1,2,3,4,5,6,7,8,9},B9))>0,COUNT(FIND({0,1,2,3,4,5,6,7,8,9},B9))>0,"")} | M9: {=IFERROR(_xlfn.IFS(R9="Count",RANDBETWEEN(1,COUNTIF($R$11:$R$653,"Count")),R9="Length",RANDBETWEEN(1,COUNTIF($R$11:$R$653,"Length"))),"")} | N9: =IFERROR(_xlfn.RANK.EQ(M9,$M$11:$M$653)+COUNTIF($M9:M$11,M9)-1,"") | O9: =IF(A9='DATA SHEET'!$L$36,C9,IFERROR(IF(AND(ISTEXT(I9),ISBLANK(C9)),"No details",VLOOKUP(C9,DimFolder,2,FALSE)),"")) | P9: =IF(AND(ISBLANK(B9),ISBLANK(C9)),"",CONCATENATE("Structural\Structural Steel\",A9,"\",O9)) | Q9: =IF(AND(ISBLANK(B9),ISBLANK(C9)),"",I9) | R9: {=IF(INDEX(Table2[],_xlfn.XMATCH($A9,Table2[Steel Member],0),_xlfn.XMATCH(R$2,Table2[#Headers],0))=0,"",INDEX(Table2[],_xlfn.XMATCH($A9,Table2[Steel Member],0),_xlfn.XMATCH(R$2,Table2[#Headers],0)))} -> #N/A | S9: {=IF(INDEX(Table2[],_xlfn.XMATCH($A9,Table2[Steel Member],0),_xlfn.XMATCH(S$2,Table2[#Headers],0))=0,"",INDEX(Table2[],_xlfn.XMATCH($A9,Table2[Steel Member],0),_xlfn.XMATCH(S$2,Table2[#Headers],0)))} -> #N/A | T9: =IF(AND(ISBLANK(B9),ISBLANK(C9)),"","t") | U9: {=IF(INDEX(Table2[],_xlfn.XMATCH($A9,Table2[Steel Member],0),_xlfn.XMATCH(U$2,Table2[#Headers],0))=0,"",INDEX(Table2[],_xlfn.XMATCH($A9,Table2[Steel Member],0),_xlfn.XMATCH(U$2,Table2[#Headers],0)))} -> #N/A | V9: =IF(AND(ISBLANK(B9),ISBLANK(C9)),"","Red") | W9: {=IF(INDEX(Table2[],_xlfn.XMATCH($A9,Table2[Steel Member],0),_xlfn.XMATCH(W$2,Table2[#Headers],0))=0,"",INDEX(Table2[],_xlfn.XMATCH($A9,Table2[Steel Member],0),_xlfn.XMATCH(W$2,Table2[#Headers],0)))} -> #N/A | X9: =W9 -> #N/A | Y9: {=IF(INDEX(Table2[],_xlfn.XMATCH($A9,Table2[Steel Member],0),_xlfn.XMATCH(Y$2,Table2[#Headers],0))=0,"",INDEX(Table2[],_xlfn.XMATCH($A9,Table2[Steel Member],0),_xlfn.XMATCH(Y$2,Table2[#Headers],0)))} -> #N/A | Z9: {=IF(INDEX(Table2[],_xlfn.XMATCH($A9,Table2[Steel Member],0),_xlfn.XMATCH(Z$2,Table2[#Headers],0))=0,"",INDEX(Table2[],_xlfn.XMATCH($A9,Table2[Steel Member],0),_xlfn.XMATCH(Z$2,Table2[#Headers],0)))} -> #N/A | AA9: {=IF(INDEX(Table2[],_xlfn.XMATCH($A9,Table2[Steel Member],0),_xlfn.XMATCH(AA$2,Table2[#Headers],0))=0,"",INDEX(Table2[],_xlfn.XMATCH($A9,Table2[Steel Member],0),_xlfn.XMATCH(AA$2,Table2[#Headers],0)))} -> #N/A | AB9: {=IF(INDEX(Table2[],_xlfn.XMATCH($A9,Table2[Steel Member],0),_xlfn.XMATCH(AB$2,Table2[#Headers],0))=0,"",INDEX(Table2[],_xlfn.XMATCH($A9,Table2[Steel Member],0),_xlfn.XMATCH(AB$2,Table2[#Headers],0)))} -> #N/A | AC9: {=IFERROR(INDEX(Table8[],_xlfn.XMATCH($O9,Table8[Dimension Name Category],0),_xlfn.XMATCH(AC$2&IF($L9," w/ tag"," w/o tag"),Table8[#Headers],0)),"")} | AD9: =IF(OR($AC9="",$AC9=0),"",IF($A9=Column,"{Length}*XNUMBER({Dimension Group Name},"&$AC9&")/1000","{Length}*XNUMBER({Dimension Group Name},"&$AC9&")/1000*{Slope Factor}")) | AE9: =IF(AND(ISBLANK(B9),ISBLANK(C9)),"",IF($A9=Purlins_Girths_Bracings,"","Steel Surface Area")) | AF9: =IF(AND(ISBLANK(B9),ISBLANK(C9)),"",IF($A9=Purlins_Girths_Bracings,"","m2")) | AG9: {=IFERROR(INDEX(Table8[],_xlfn.XMATCH($O9,Table8[Dimension Name Category],0),_xlfn.XMATCH(AG$2&IF($L9," w/ tag"," w/o tag"),Table8[#Headers],0)),"")} | AH9: =IF(OR($AG9="",$AG9=0),"",IF($A9=Column,"{Length}*XNUMBER({Dimension Group Name},"&$AG9&")/1000","{Length}*XNUMBER({Dimension Group Name},"&$AG9&")/1000*{Slope Factor}")) | AJ9: =IF(OR($A9=Column,$A9=""),"","Slope Length") | AK9: =IF(OR($A9=Column,$A9=""),"","m") | AL9: {=IF(INDEX(Table2[],_xlfn.XMATCH($A9,Table2[Steel Member],0),_xlfn.XMATCH(AL$2,Table2[#Headers],0))=0,"",INDEX(Table2[],_xlfn.XMATCH($A9,Table2[Steel Member],0),_xlfn.XMATCH(AL$2,Table2[#Headers],0)))} -> #N/A | AN9: =IF(OR($A9=Column,$A9=""),"","Slope Factor") | AP9: {=IF(INDEX(Table2[],_xlfn.XMATCH($A9,Table2[Steel Member],0),_xlfn.XMATCH(AP$2,Table2[#Headers],0))=0,"",INDEX(Table2[],_xlfn.XMATCH($A9,Table2[Steel Member],0),_xlfn.XMATCH(AP$2,Table2[#Headers],0)))} -> #N/A
A10: INSERT DATA HERE | L10: DELETE THIS ROW | M10: DELETE THIS ROW | N10: DELETE THIS ROW | O10: DELETE THIS ROW | P10: DELETE THIS ROW | Q10: DELETE THIS ROW | R10: DELETE THIS ROW | S10: DELETE THIS ROW | T10: DELETE THIS ROW | U10: DELETE THIS ROW | V10: DELETE THIS ROW | W10: DELETE THIS ROW | X10: DELETE THIS ROW | Y10: DELETE THIS ROW | Z10: DELETE THIS ROW | AA10: DELETE THIS ROW | AB10: DELETE THIS ROW | AC10: DELETE THIS ROW | AD10: DELETE THIS ROW | AE10: DELETE THIS ROW | AF10: DELETE THIS ROW | AG10: DELETE THIS ROW | AH10: DELETE THIS ROW | AI10: DELETE THIS ROW | AJ10: DELETE THIS ROW | AK10: DELETE THIS ROW | AL10: DELETE THIS ROW | AM10: DELETE THIS ROW | AN10: DELETE THIS ROW | AO10: DELETE THIS ROW | AP10: DELETE THIS ROW | AQ10: DELETE THIS ROW | AR10: DELETE THIS ROW | AS10: DELETE THIS ROW | AT10: DELETE THIS ROW
A11: Purlins, Girts and Bracings | C11: Purlins | E11: C15019 | F11: {=IF(COUNT(FIND(PurlinsxGirthsxBracings,$C11))>0,0,ROUNDUP(IF(D11=0,0,VLOOKUP(D11,'DATA SHEET'!$B:$D,2,FALSE)),2))} -> 0 | G11: {=IF(COUNT(FIND(PurlinsxGirthsxBracings,$C11))>0,0,ROUNDUP(IF(D11=0,0,VLOOKUP(D11,'DATA SHEET'!$B:$D,3,FALSE)),2))} -> 0 | I11: {=IF(AND(ISBLANK(B11),ISBLANK(C11),ISBLANK(E11)),0,IF(COUNT(FIND(PurlinsxGirthsxBracings,$C11))>0,IF(B11=0,CONCATENATE(E11," ",C11),CONCATENATE(B11," - ",E11," ",C11)),IF(B11=0,IF(ISBLANK(C11),E11,CONCATENATE(D11,", ",F11,"kg/m, ",G11,"mm surface perimeter")),IF(AND(ISBLANK(C11),ISTEXT(E11)),CONCATENATE(B11," - ",E11),IF(AND(ISBLANK(C11),ISBLANK(E11)),B11,CONCATENATE(B11," - ",D11,", ",F11,"kg/m, ",G11,"mm surface perimeter"))))&IF(ISBLANK(H11),"",H11)))} -> C15019 Purlins | L11: {=IF(COUNT(FIND({0,1,2,3,4,5,6,7,8,9},B11))>0,COUNT(FIND({0,1,2,3,4,5,6,7,8,9},B11))>0,"")} | M11: {=IFERROR(_xlfn.IFS(R11="Count",RANDBETWEEN(1,COUNTIF($R$11:$R$653,"Count")),R11="Length",RANDBETWEEN(1,COUNTIF($R$11:$R$653,"Length"))),"")} -> 7 | N11: =IFERROR(_xlfn.RANK.EQ(M11,$M$11:$M$653)+COUNTIF($M11:M$11,M11)-1,"") -> 7 | O11: =IF(A11='DATA SHEET'!$L$36,C11,IFERROR(IF(AND(ISTEXT(I11),ISBLANK(C11)),"No details",VLOOKUP(C11,DimFolder,2,FALSE)),"")) -> Purlins | P11: =IF(AND(ISBLANK(B11),ISBLANK(C11)),"",CONCATENATE("Structural\Structural Steel\",A11,"\",O11)) -> Structural\Structural Steel\Purlins, Girts and Bracings\Purlins | Q11: =IF(AND(ISBLANK(B11),ISBLANK(C11)),"",I11) -> C15019 Purlins | R11: {=IF(INDEX(Table2[],_xlfn.XMATCH($A11,Table2[Steel Member],0),_xlfn.XMATCH(R$2,Table2[#Headers],0))=0,"",INDEX(Table2[],_xlfn.XMATCH($A11,Table2[Steel Member],0),_xlfn.XMATCH(R$2,Table2[#Headers],0)))} -> Length | S11: {=IF(INDEX(Table2[],_xlfn.XMATCH($A11,Table2[Steel Member],0),_xlfn.XMATCH(S$2,Table2[#Headers],0))=0,"",INDEX(Table2[],_xlfn.XMATCH($A11,Table2[Steel Member],0),_xlfn.XMATCH(S$2,Table2[#Headers],0)))} -> Slope Length | T11: =IF(AND(ISBLANK(B11),ISBLANK(C11)),"","t") -> t | U11: =VLOOKUP(N11,'COLOR CODE'!$B:$D,2,FALSE) -> 0,250,154 | V11: =IF(AND(ISBLANK(B11),ISBLANK(C11)),"","Red") -> Red | W11: {=IF(INDEX(Table2[],_xlfn.XMATCH($A11,Table2[Steel Member],0),_xlfn.XMATCH(W$2,Table2[#Headers],0))=0,"",INDEX(Table2[],_xlfn.XMATCH($A11,Table2[Steel Member],0),_xlfn.XMATCH(W$2,Table2[#Headers],0)))} | X11: =W11 | Y11: {=IF(INDEX(Table2[],_xlfn.XMATCH($A11,Table2[Steel Member],0),_xlfn.XMATCH(Y$2,Table2[#Headers],0))=0,"",INDEX(Table2[],_xlfn.XMATCH($A11,Table2[Steel Member],0),_xlfn.XMATCH(Y$2,Table2[#Headers],0)))} -> "0 degrees" | Z11: {=IF(INDEX(Table2[],_xlfn.XMATCH($A11,Table2[Steel Member],0),_xlfn.XMATCH(Z$2,Table2[#Headers],0))=0,"",INDEX(Table2[],_xlfn.XMATCH($A11,Table2[Steel Member],0),_xlfn.XMATCH(Z$2,Table2[#Headers],0)))} | AA11: {=IF(INDEX(Table2[],_xlfn.XMATCH($A11,Table2[Steel Member],0),_xlfn.XMATCH(AA$2,Table2[#Headers],0))=0,"",INDEX(Table2[],_xlfn.XMATCH($A11,Table2[Steel Member],0),_xlfn.XMATCH(AA$2,Table2[#Headers],0)))} -> [Count] | AB11: {=IF(INDEX(Table2[],_xlfn.XMATCH($A11,Table2[Steel Member],0),_xlfn.XMATCH(AB$2,Table2[#Headers],0))=0,"",INDEX(Table2[],_xlfn.XMATCH($A11,Table2[Steel Member],0),_xlfn.XMATCH(AB$2,Table2[#Headers],0)))} -> [Length] | AC11: {=IFERROR(INDEX(Table8[],_xlfn.XMATCH($O11,Table8[Dimension Name Category],0),_xlfn.XMATCH(AC$2&IF($L11," w/ tag"," w/o tag"),Table8[#Headers],0)),"")} | AD11: =IF(OR($AC11="",$AC11=0),"",IF($A11=Column,"{Length}*XNUMBER({Dimension Group Name},"&$AC11&")/1000","{Length}*XNUMBER({Dimension Group Name},"&$AC11&")/1000*{Slope Factor}")) | AE11: =IF(AND(ISBLANK(B11),ISBLANK(C11)),"",IF($A11=Purlins_Girths_Bracings,"","Steel Surface Area")) | AF11: =IF(AND(ISBLANK(B11),ISBLANK(C11)),"",IF($A11=Purlins_Girths_Bracings,"","m2")) | AG11: {=IFERROR(INDEX(Table8[],_xlfn.XMATCH($O11,Table8[Dimension Name Category],0),_xlfn.XMATCH(AG$2&IF($L11," w/ tag"," w/o tag"),Table8[#Headers],0)),"")} | AH11: =IF(OR($AG11="",$AG11=0),"",IF($A11=Column,"{Length}*XNUMBER({Dimension Group Name},"&$AG11&")/1000","{Length}*XNUMBER({Dimension Group Name},"&$AG11&")/1000*{Slope Factor}")) | AJ11: =IF(OR($A11=Column,$A11=""),"","Slope Length") -> Slope Length | AK11: =IF(OR($A11=Column,$A11=""),"","m") -> m | AL11: {=IF(INDEX(Table2[],_xlfn.XMATCH($A11,Table2[Steel Member],0),_xlfn.XMATCH(AL$2,Table2[#Headers],0))=0,"",INDEX(Table2[],_xlfn.XMATCH($A11,Table2[Steel Member],0),_xlfn.XMATCH(AL$2,Table2[#Headers],0)))} -> [Length]*{Slope Factor} | AN11: =IF(OR($A11=Column,$A11=""),"","Slope Factor") -> Slope Factor | AP11: {=IF(INDEX(Table2[],_xlfn.XMATCH($A11,Table2[Steel Member],0),_xlfn.XMATCH(AP$2,Table2[#Headers],0))=0,"",INDEX(Table2[],_xlfn.XMATCH($A11,Table2[Steel Member],0),_xlfn.XMATCH(AP$2,Table2[#Headers],0)))} -> 1/COS(RADIANS(XNUMBER({Dimension Name},1)))
A12: Framing | B12: B20a | C12: UB | D12: 200UB18.2 | F12: {=IF(COUNT(FIND(PurlinsxGirthsxBracings,$C12))>0,0,ROUNDUP(IF(D12=0,0,VLOOKUP(D12,'DATA SHEET'!$B:$D,2,FALSE)),2))} -> 18.2 | G12: {=IF(COUNT(FIND(PurlinsxGirthsxBracings,$C12))>0,0,ROUNDUP(IF(D12=0,0,VLOOKUP(D12,'DATA SHEET'!$B:$D,3,FALSE)),2))} -> 783 | I12: {=IF(AND(ISBLANK(B12),ISBLANK(C12),ISBLANK(E12)),0,IF(COUNT(FIND(PurlinsxGirthsxBracings,$C12))>0,IF(B12=0,CONCATENATE(E12," ",C12),CONCATENATE(B12," - ",E12," ",C12)),IF(B12=0,IF(ISBLANK(C12),E12,CONCATENATE(D12,", ",F12,"kg/m, ",G12,"mm surface perimeter")),IF(AND(ISBLANK(C12),ISTEXT(E12)),CONCATENATE(B12," - ",E12),IF(AND(ISBLANK(C12),ISBLANK(E12)),B12,CONCATENATE(B12," - ",D12,", ",F12,"kg/m, ",G12,"mm surface perimeter"))))&IF(ISBLANK(H12),"",H12)))} -> B20a - 200UB18.2, 18.2kg/m, 783mm surface perimeter | L12: {=IF(COUNT(FIND({0,1,2,3,4,5,6,7,8,9},B12))>0,COUNT(FIND({0,1,2,3,4,5,6,7,8,9},B12))>0,"")} -> TRUE | M12: {=IFERROR(_xlfn.IFS(R12="Count",RANDBETWEEN(1,COUNTIF($R$11:$R$653,"Count")),R12="Length",RANDBETWEEN(1,COUNTIF($R$11:$R$653,"Length"))),"")} -> 8 | N12: =IFERROR(_xlfn.RANK.EQ(M12,$M$11:$M$653)+COUNTIF($M$11:M12,M12)-1,"") -> 6 | O12: =IF(A12='DATA SHEET'!$L$36,C12,IFERROR(IF(AND(ISTEXT(I12),ISBLANK(C12)),"No details",VLOOKUP(C12,DimFolder,2,FALSE)),"")) -> CHS, UB, UC, WB, WC, BT, CT | P12: =IF(AND(ISBLANK(B12),ISBLANK(C12)),"",CONCATENATE("Structural\Structural Steel\",A12,"\",O12)) -> Structural\Structural Steel\Framing\CHS, UB, UC, WB, WC, BT, CT | Q12: =IF(AND(ISBLANK(B12),ISBLANK(C12)),"",I12) -> B20a - 200UB18.2, 18.2kg/m, 783mm surface perimeter | R12: {=IF(INDEX(Table2[],_xlfn.XMATCH($A12,Table2[Steel Member],0),_xlfn.XMATCH(R$2,Table2[#Headers],0))=0,"",INDEX(Table2[],_xlfn.XMATCH($A12,Table2[Steel Member],0),_xlfn.XMATCH(R$2,Table2[#Headers],0)))} -> Length | S12: {=IF(INDEX(Table2[],_xlfn.XMATCH($A12,Table2[Steel Member],0),_xlfn.XMATCH(S$2,Table2[#Headers],0))=0,"",INDEX(Table2[],_xlfn.XMATCH($A12,Table2[Steel Member],0),_xlfn.XMATCH(S$2,Table2[#Headers],0)))} -> Weight | T12: =IF(AND(ISBLANK(B12),ISBLANK(C12)),"","t") -> t | U12: =VLOOKUP(N12,'COLOR CODE'!$B:$D,2,FALSE) -> 0,128,128 | V12: =IF(AND(ISBLANK(B12),ISBLANK(C12)),"","Red") -> Red | W12: {=IF(INDEX(Table2[],_xlfn.XMATCH($A12,Table2[Steel Member],0),_xlfn.XMATCH(W$2,Table2[#Headers],0))=0,"",INDEX(Table2[],_xlfn.XMATCH($A12,Table2[Steel Member],0),_xlfn.XMATCH(W$2,Table2[#Headers],0)))} | X12: =W12 | Y12: {=IF(INDEX(Table2[],_xlfn.XMATCH($A12,Table2[Steel Member],0),_xlfn.XMATCH(Y$2,Table2[#Headers],0))=0,"",INDEX(Table2[],_xlfn.XMATCH($A12,Table2[Steel Member],0),_xlfn.XMATCH(Y$2,Table2[#Headers],0)))} -> "0 degrees" | Z12: {=IF(INDEX(Table2[],_xlfn.XMATCH($A12,Table2[Steel Member],0),_xlfn.XMATCH(Z$2,Table2[#Headers],0))=0,"",INDEX(Table2[],_xlfn.XMATCH($A12,Table2[Steel Member],0),_xlfn.XMATCH(Z$2,Table2[#Headers],0)))} | AA12: {=IF(INDEX(Table2[],_xlfn.XMATCH($A12,Table2[Steel Member],0),_xlfn.XMATCH(AA$2,Table2[#Headers],0))=0,"",INDEX(Table2[],_xlfn.XMATCH($A12,Table2[Steel Member],0),_xlfn.XMATCH(AA$2,Table2[#Headers],0)))} -> [Count] | AB12: {=IF(INDEX(Table2[],_xlfn.XMATCH($A12,Table2[Steel Member],0),_xlfn.XMATCH(AB$2,Table2[#Headers],0))=0,"",INDEX(Table2[],_xlfn.XMATCH($A12,Table2[Steel Member],0),_xlfn.XMATCH(AB$2,Table2[#Headers],0)))} -> [Length] | AC12: {=IFERROR(INDEX(Table8[],_xlfn.XMATCH($O12,Table8[Dimension Name Category],0),_xlfn.XMATCH(AC$2&IF($L12," w/ tag"," w/o tag"),Table8[#Headers],0)),"")} -> 4 | AD12: =IF(OR($AC12="",$AC12=0),"",IF($A12=Column,"{Length}*XNUMBER({Dimension Group Name},"&$AC12&")/1000","{Length}*XNUMBER({Dimension Group Name},"&$AC12&")/1000*{Slope Factor}")) -> {Length}*XNUMBER({Dimension Group Name},4)/1000*{Slope Factor} | AE12: =IF(AND(ISBLANK(B12),ISBLANK(C12)),"",IF($A12=Purlins_Girths_Bracings,"","Steel Surface Area")) -> Steel Surface Area | AF12: =IF(AND(ISBLANK(B12),ISBLANK(C12)),"",IF($A12=Purlins_Girths_Bracings,"","m2")) -> m2 | AG12: {=IFERROR(INDEX(Table8[],_xlfn.XMATCH($O12,Table8[Dimension Name Category],0),_xlfn.XMATCH(AG$2&IF($L12," w/ tag"," w/o tag"),Table8[#Headers],0)),"")} -> 5 | AH12: =IF(OR($AG12="",$AG12=0),"",IF($A12=Column,"{Length}*XNUMBER({Dimension Group Name},"&$AG12&")/1000","{Length}*XNUMBER({Dimension Group Name},"&$AG12&")/1000*{Slope Factor}")) -> {Length}*XNUMBER({Dimension Group Name},5)/1000*{Slope Factor} | AJ12: =IF(OR($A12=Column,$A12=""),"","Slope Length") -> Slope Length | AK12: =IF(OR($A12=Column,$A12=""),"","m") -> m | AL12: {=IF(INDEX(Table2[],_xlfn.XMATCH($A12,Table2[Steel Member],0),_xlfn.XMATCH(AL$2,Table2[#Headers],0))=0,"",INDEX(Table2[],_xlfn.XMATCH($A12,Table2[Steel Member],0),_xlfn.XMATCH(AL$2,Table2[#Headers],0)))} -> [Length]*{Slope Factor} | AN12: =IF(OR($A12=Column,$A12=""),"","Slope Factor") -> Slope Factor | AP12: {=IF(INDEX(Table2[],_xlfn.XMATCH($A12,Table2[Steel Member],0),_xlfn.XMATCH(AP$2,Table2[#Headers],0))=0,"",INDEX(Table2[],_xlfn.XMATCH($A12,Table2[Steel Member],0),_xlfn.XMATCH(AP$2,Table2[#Headers],0)))} -> 1/COS(RADIANS(XNUMBER({Dimension Name},1)))
A13: Framing | B13: B20c | C13: UB | D13: 200UB25.4 | F13: {=IF(COUNT(FIND(PurlinsxGirthsxBracings,$C13))>0,0,ROUNDUP(IF(D13=0,0,VLOOKUP(D13,'DATA SHEET'!$B:$D,2,FALSE)),2))} -> 25.4 | G13: {=IF(COUNT(FIND(PurlinsxGirthsxBracings,$C13))>0,0,ROUNDUP(IF(D13=0,0,VLOOKUP(D13,'DATA SHEET'!$B:$D,3,FALSE)),2))} -> 926.4 | I13: {=IF(AND(ISBLANK(B13),ISBLANK(C13),ISBLANK(E13)),0,IF(COUNT(FIND(PurlinsxGirthsxBracings,$C13))>0,IF(B13=0,CONCATENATE(E13," ",C13),CONCATENATE(B13," - ",E13," ",C13)),IF(B13=0,IF(ISBLANK(C13),E13,CONCATENATE(D13,", ",F13,"kg/m, ",G13,"mm surface perimeter")),IF(AND(ISBLANK(C13),ISTEXT(E13)),CONCATENATE(B13," - ",E13),IF(AND(ISBLANK(C13),ISBLANK(E13)),B13,CONCATENATE(B13," - ",D13,", ",F13,"kg/m, ",G13,"mm surface perimeter"))))&IF(ISBLANK(H13),"",H13)))} -> B20c - 200UB25.4, 25.4kg/m, 926.4mm surface perimeter | L13: {=IF(COUNT(FIND({0,1,2,3,4,5,6,7,8,9},B13))>0,COUNT(FIND({0,1,2,3,4,5,6,7,8,9},B13))>0,"")} -> TRUE | M13: {=IFERROR(_xlfn.IFS(R13="Count",RANDBETWEEN(1,COUNTIF($R$11:$R$653,"Count")),R13="Length",RANDBETWEEN(1,COUNTIF($R$11:$R$653,"Length"))),"")} -> 13 | N13: =IFERROR(_xlfn.RANK.EQ(M13,$M$11:$M$653)+COUNTIF($M$11:M13,M13)-1,"") -> 3 | O13: =IF(A13='DATA SHEET'!$L$36,C13,IFERROR(IF(AND(ISTEXT(I13),ISBLANK(C13)),"No details",VLOOKUP(C13,DimFolder,2,FALSE)),"")) -> CHS, UB, UC, WB, WC, BT, CT | P13: =IF(AND(ISBLANK(B13),ISBLANK(C13)),"",CONCATENATE("Structural\Structural Steel\",A13,"\",O13)) -> Structural\Structural Steel\Framing\CHS, UB, UC, WB, WC, BT, CT | Q13: =IF(AND(ISBLANK(B13),ISBLANK(C13)),"",I13) -> B20c - 200UB25.4, 25.4kg/m, 926.4mm surface perimeter | R13: {=IF(INDEX(Table2[],_xlfn.XMATCH($A13,Table2[Steel Member],0),_xlfn.XMATCH(R$2,Table2[#Headers],0))=0,"",INDEX(Table2[],_xlfn.XMATCH($A13,Table2[Steel Member],0),_xlfn.XMATCH(R$2,Table2[#Headers],0)))} -> Length | S13: {=IF(INDEX(Table2[],_xlfn.XMATCH($A13,Table2[Steel Member],0),_xlfn.XMATCH(S$2,Table2[#Headers],0))=0,"",INDEX(Table2[],_xlfn.XMATCH($A13,Table2[Steel Member],0),_xlfn.XMATCH(S$2,Table2[#Headers],0)))} -> Weight | T13: =IF(AND(ISBLANK(B13),ISBLANK(C13)),"","t") -> t | U13: =VLOOKUP(N13,'COLOR CODE'!$B:$D,2,FALSE) -> 0,0,128 | V13: =IF(AND(ISBLANK(B13),ISBLANK(C13)),"","Red") -> Red | W13: {=IF(INDEX(Table2[],_xlfn.XMATCH($A13,Table2[Steel Member],0),_xlfn.XMATCH(W$2,Table2[#Headers],0))=0,"",INDEX(Table2[],_xlfn.XMATCH($A13,Table2[Steel Member],0),_xlfn.XMATCH(W$2,Table2[#Headers],0)))} | X13: =W13 | Y13: {=IF(INDEX(Table2[],_xlfn.XMATCH($A13,Table2[Steel Member],0),_xlfn.XMATCH(Y$2,Table2[#Headers],0))=0,"",INDEX(Table2[],_xlfn.XMATCH($A13,Table2[Steel Member],0),_xlfn.XMATCH(Y$2,Table2[#Headers],0)))} -> "0 degrees" | Z13: {=IF(INDEX(Table2[],_xlfn.XMATCH($A13,Table2[Steel Member],0),_xlfn.XMATCH(Z$2,Table2[#Headers],0))=0,"",INDEX(Table2[],_xlfn.XMATCH($A13,Table2[Steel Member],0),_xlfn.XMATCH(Z$2,Table2[#Headers],0)))} | AA13: {=IF(INDEX(Table2[],_xlfn.XMATCH($A13,Table2[Steel Member],0),_xlfn.XMATCH(AA$2,Table2[#Headers],0))=0,"",INDEX(Table2[],_xlfn.XMATCH($A13,Table2[Steel Member],0),_xlfn.XMATCH(AA$2,Table2[#Headers],0)))} -> [Count] | AB13: {=IF(INDEX(Table2[],_xlfn.XMATCH($A13,Table2[Steel Member],0),_xlfn.XMATCH(AB$2,Table2[#Headers],0))=0,"",INDEX(Table2[],_xlfn.XMATCH($A13,Table2[Steel Member],0),_xlfn.XMATCH(AB$2,Table2[#Headers],0)))} -> [Length] | AC13: {=IFERROR(INDEX(Table8[],_xlfn.XMATCH($O13,Table8[Dimension Name Category],0),_xlfn.XMATCH(AC$2&IF($L13," w/ tag"," w/o tag"),Table8[#Headers],0)),"")} -> 4 | AD13: =IF(OR($AC13="",$AC13=0),"",IF($A13=Column,"{Length}*XNUMBER({Dimension Group Name},"&$AC13&")/1000","{Length}*XNUMBER({Dimension Group Name},"&$AC13&")/1000*{Slope Factor}")) -> {Length}*XNUMBER({Dimension Group Name},4)/1000*{Slope Factor} | AE13: =IF(AND(ISBLANK(B13),ISBLANK(C13)),"",IF($A13=Purlins_Girths_Bracings,"","Steel Surface Area")) -> Steel Surface Area | AF13: =IF(AND(ISBLANK(B13),ISBLANK(C13)),"",IF($A13=Purlins_Girths_Bracings,"","m2")) -> m2 | AG13: {=IFERROR(INDEX(Table8[],_xlfn.XMATCH($O13,Table8[Dimension Name Category],0),_xlfn.XMATCH(AG$2&IF($L13," w/ tag"," w/o tag"),Table8[#Headers],0)),"")} -> 5 | AH13: =IF(OR($AG13="",$AG13=0),"",IF($A13=Column,"{Length}*XNUMBER({Dimension Group Name},"&$AG13&")/1000","{Length}*XNUMBER({Dimension Group Name},"&$AG13&")/1000*{Slope Factor}")) -> {Length}*XNUMBER({Dimension Group Name},5)/1000*{Slope Factor} | AJ13: =IF(OR($A13=Column,$A13=""),"","Slope Length") -> Slope Length | AK13: =IF(OR($A13=Column,$A13=""),"","m") -> m | AL13: {=IF(INDEX(Table2[],_xlfn.XMATCH($A13,Table2[Steel Member],0),_xlfn.XMATCH(AL$2,Table2[#Headers],0))=0,"",INDEX(Table2[],_xlfn.XMATCH($A13,Table2[Steel Member],0),_xlfn.XMATCH(AL$2,Table2[#Headers],0)))} -> [Length]*{Slope Factor} | AN13: =IF(OR($A13=Column,$A13=""),"","Slope Factor") -> Slope Factor | AP13: {=IF(INDEX(Table2[],_xlfn.XMATCH($A13,Table2[Steel Member],0),_xlfn.XMATCH(AP$2,Table2[#Headers],0))=0,"",INDEX(Table2[],_xlfn.XMATCH($A13,Table2[Steel Member],0),_xlfn.XMATCH(AP$2,Table2[#Headers],0)))} -> 1/COS(RADIANS(XNUMBER({Dimension Name},1)))
A14: Framing | B14: B25a | C14: UB | D14: 250UB25.7 | F14: {=IF(COUNT(FIND(PurlinsxGirthsxBracings,$C14))>0,0,ROUNDUP(IF(D14=0,0,VLOOKUP(D14,'DATA SHEET'!$B:$D,2,FALSE)),2))} -> 25.7 | G14: {=IF(COUNT(FIND(PurlinsxGirthsxBracings,$C14))>0,0,ROUNDUP(IF(D14=0,0,VLOOKUP(D14,'DATA SHEET'!$B:$D,3,FALSE)),2))} -> 982 | I14: {=IF(AND(ISBLANK(B14),ISBLANK(C14),ISBLANK(E14)),0,IF(COUNT(FIND(PurlinsxGirthsxBracings,$C14))>0,IF(B14=0,CONCATENATE(E14," ",C14),CONCATENATE(B14," - ",E14," ",C14)),IF(B14=0,IF(ISBLANK(C14),E14,CONCATENATE(D14,", ",F14,"kg/m, ",G14,"mm surface perimeter")),IF(AND(ISBLANK(C14),ISTEXT(E14)),CONCATENATE(B14," - ",E14),IF(AND(ISBLANK(C14),ISBLANK(E14)),B14,CONCATENATE(B14," - ",D14,", ",F14,"kg/m, ",G14,"mm surface perimeter"))))&IF(ISBLANK(H14),"",H14)))} -> B25a - 250UB25.7, 25.7kg/m, 982mm surface perimeter | L14: {=IF(COUNT(FIND({0,1,2,3,4,5,6,7,8,9},B14))>0,COUNT(FIND({0,1,2,3,4,5,6,7,8,9},B14))>0,"")} -> TRUE | M14: {=IFERROR(_xlfn.IFS(R14="Count",RANDBETWEEN(1,COUNTIF($R$11:$R$653,"Count")),R14="Length",RANDBETWEEN(1,COUNTIF($R$11:$R$653,"Length"))),"")} -> 9 | N14: =IFERROR(_xlfn.RANK.EQ(M14,$M$11:$M$653)+COUNTIF($M$11:M14,M14)-1,"") -> 5 | O14: =IF(A14='DATA SHEET'!$L$36,C14,IFERROR(IF(AND(ISTEXT(I14),ISBLANK(C14)),"No details",VLOOKUP(C14,DimFolder,2,FALSE)),"")) -> CHS, UB, UC, WB, WC, BT, CT | P14: =IF(AND(ISBLANK(B14),ISBLANK(C14)),"",CONCATENATE("Structural\Structural Steel\",A14,"\",O14)) -> Structural\Structural Steel\Framing\CHS, UB, UC, WB, WC, BT, CT | Q14: =IF(AND(ISBLANK(B14),ISBLANK(C14)),"",I14) -> B25a - 250UB25.7, 25.7kg/m, 982mm surface perimeter | R14: {=IF(INDEX(Table2[],_xlfn.XMATCH($A14,Table2[Steel Member],0),_xlfn.XMATCH(R$2,Table2[#Headers],0))=0,"",INDEX(Table2[],_xlfn.XMATCH($A14,Table2[Steel Member],0),_xlfn.XMATCH(R$2,Table2[#Headers],0)))} -> Length | S14: {=IF(INDEX(Table2[],_xlfn.XMATCH($A14,Table2[Steel Member],0),_xlfn.XMATCH(S$2,Table2[#Headers],0))=0,"",INDEX(Table2[],_xlfn.XMATCH($A14,Table2[Steel Member],0),_xlfn.XMATCH(S$2,Table2[#Headers],0)))} -> Weight | T14: =IF(AND(ISBLANK(B14),ISBLANK(C14)),"","t") -> t | U14: =VLOOKUP(N14,'COLOR CODE'!$B:$D,2,FALSE) -> 0,128,0 | V14: =IF(AND(ISBLANK(B14),ISBLANK(C14)),"","Red") -> Red | W14: {=IF(INDEX(Table2[],_xlfn.XMATCH($A14,Table2[Steel Member],0),_xlfn.XMATCH(W$2,Table2[#Headers],0))=0,"",INDEX(Table2[],_xlfn.XMATCH($A14,Table2[Steel Member],0),_xlfn.XMATCH(W$2,Table2[#Headers],0)))} | X14: =W14 | Y14: {=IF(INDEX(Table2[],_xlfn.XMATCH($A14,Table2[Steel Member],0),_xlfn.XMATCH(Y$2,Table2[#Headers],0))=0,"",INDEX(Table2[],_xlfn.XMATCH($A14,Table2[Steel Member],0),_xlfn.XMATCH(Y$2,Table2[#Headers],0)))} -> "0 degrees" | Z14: {=IF(INDEX(Table2[],_xlfn.XMATCH($A14,Table2[Steel Member],0),_xlfn.XMATCH(Z$2,Table2[#Headers],0))=0,"",INDEX(Table2[],_xlfn.XMATCH($A14,Table2[Steel Member],0),_xlfn.XMATCH(Z$2,Table2[#Headers],0)))} | AA14: {=IF(INDEX(Table2[],_xlfn.XMATCH($A14,Table2[Steel Member],0),_xlfn.XMATCH(AA$2,Table2[#Headers],0))=0,"",INDEX(Table2[],_xlfn.XMATCH($A14,Table2[Steel Member],0),_xlfn.XMATCH(AA$2,Table2[#Headers],0)))} -> [Count] | AB14: {=IF(INDEX(Table2[],_xlfn.XMATCH($A14,Table2[Steel Member],0),_xlfn.XMATCH(AB$2,Table2[#Headers],0))=0,"",INDEX(Table2[],_xlfn.XMATCH($A14,Table2[Steel Member],0),_xlfn.XMATCH(AB$2,Table2[#Headers],0)))} -> [Length] | AC14: {=IFERROR(INDEX(Table8[],_xlfn.XMATCH($O14,Table8[Dimension Name Category],0),_xlfn.XMATCH(AC$2&IF($L14," w/ tag"," w/o tag"),Table8[#Headers],0)),"")} -> 4 | AD14: =IF(OR($AC14="",$AC14=0),"",IF($A14=Column,"{Length}*XNUMBER({Dimension Group Name},"&$AC14&")/1000","{Length}*XNUMBER({Dimension Group Name},"&$AC14&")/1000*{Slope Factor}")) -> {Length}*XNUMBER({Dimension Group Name},4)/1000*{Slope Factor} | AE14: =IF(AND(ISBLANK(B14),ISBLANK(C14)),"",IF($A14=Purlins_Girths_Bracings,"","Steel Surface Area")) -> Steel Surface Area | AF14: =IF(AND(ISBLANK(B14),ISBLANK(C14)),"",IF($A14=Purlins_Girths_Bracings,"","m2")) -> m2 | AG14: {=IFERROR(INDEX(Table8[],_xlfn.XMATCH($O14,Table8[Dimension Name Category],0),_xlfn.XMATCH(AG$2&IF($L14," w/ tag"," w/o tag"),Table8[#Headers],0)),"")} -> 5 | AH14: =IF(OR($AG14="",$AG14=0),"",IF($A14=Column,"{Length}*XNUMBER({Dimension Group Name},"&$AG14&")/1000","{Length}*XNUMBER({Dimension Group Name},"&$AG14&")/1000*{Slope Factor}")) -> {Length}*XNUMBER({Dimension Group Name},5)/1000*{Slope Factor} | AJ14: =IF(OR($A14=Column,$A14=""),"","Slope Length") -> Slope Length | AK14: =IF(OR($A14=Column,$A14=""),"","m") -> m | AL14: {=IF(INDEX(Table2[],_xlfn.XMATCH($A14,Table2[Steel Member],0),_xlfn.XMATCH(AL$2,Table2[#Headers],0))=0,"",INDEX(Table2[],_xlfn.XMATCH($A14,Table2[Steel Member],0),_xlfn.XMATCH(AL$2,Table2[#Headers],0)))} -> [Length]*{Slope Factor} | AN14: =IF(OR($A14=Column,$A14=""),"","Slope Factor") -> Slope Factor | AP14: {=IF(INDEX(Table2[],_xlfn.XMATCH($A14,Table2[Steel Member],0),_xlfn.XMATCH(AP$2,Table2[#Headers],0))=0,"",INDEX(Table2[],_xlfn.XMATCH($A14,Table2[Steel Member],0),_xlfn.XMATCH(AP$2,Table2[#Headers],0)))} -> 1/COS(RADIANS(XNUMBER({Dimension Name},1)))
A15: Framing | B15: B25b | C15: UB | D15: 250UB31.4 | F15: {=IF(COUNT(FIND(PurlinsxGirthsxBracings,$C15))>0,0,ROUNDUP(IF(D15=0,0,VLOOKUP(D15,'DATA SHEET'!$B:$D,2,FALSE)),2))} -> 31.4 | G15: {=IF(COUNT(FIND(PurlinsxGirthsxBracings,$C15))>0,0,ROUNDUP(IF(D15=0,0,VLOOKUP(D15,'DATA SHEET'!$B:$D,3,FALSE)),2))} -> 1075.8 | I15: {=IF(AND(ISBLANK(B15),ISBLANK(C15),ISBLANK(E15)),0,IF(COUNT(FIND(PurlinsxGirthsxBracings,$C15))>0,IF(B15=0,CONCATENATE(E15," ",C15),CONCATENATE(B15," - ",E15," ",C15)),IF(B15=0,IF(ISBLANK(C15),E15,CONCATENATE(D15,", ",F15,"kg/m, ",G15,"mm surface perimeter")),IF(AND(ISBLANK(C15),ISTEXT(E15)),CONCATENATE(B15," - ",E15),IF(AND(ISBLANK(C15),ISBLANK(E15)),B15,CONCATENATE(B15," - ",D15,", ",F15,"kg/m, ",G15,"mm surface perimeter"))))&IF(ISBLANK(H15),"",H15)))} -> B25b - 250UB31.4, 31.4kg/m, 1075.8mm surface perimeter | L15: {=IF(COUNT(FIND({0,1,2,3,4,5,6,7,8,9},B15))>0,COUNT(FIND({0,1,2,3,4,5,6,7,8,9},B15))>0,"")} -> TRUE | M15: {=IFERROR(_xlfn.IFS(R15="Count",RANDBETWEEN(1,COUNTIF($R$11:$R$653,"Count")),R15="Length",RANDBETWEEN(1,COUNTIF($R$11:$R$653,"Length"))),"")} -> 13 | N15: =IFERROR(_xlfn.RANK.EQ(M15,$M$11:$M$653)+COUNTIF($M$11:M15,M15)-1,"") -> 4 | O15: =IF(A15='DATA SHEET'!$L$36,C15,IFERROR(IF(AND(ISTEXT(I15),ISBLANK(C15)),"No details",VLOOKUP(C15,DimFolder,2,FALSE)),"")) -> CHS, UB, UC, WB, WC, BT, CT | P15: =IF(AND(ISBLANK(B15),ISBLANK(C15)),"",CONCATENATE("Structural\Structural Steel\",A15,"\",O15)) -> Structural\Structural Steel\Framing\CHS, UB, UC, WB, WC, BT, CT | Q15: =IF(AND(ISBLANK(B15),ISBLANK(C15)),"",I15) -> B25b - 250UB31.4, 31.4kg/m, 1075.8mm surface perimeter | R15: {=IF(INDEX(Table2[],_xlfn.XMATCH($A15,Table2[Steel Member],0),_xlfn.XMATCH(R$2,Table2[#Headers],0))=0,"",INDEX(Table2[],_xlfn.XMATCH($A15,Table2[Steel Member],0),_xlfn.XMATCH(R$2,Table2[#Headers],0)))} -> Length | S15: {=IF(INDEX(Table2[],_xlfn.XMATCH($A15,Table2[Steel Member],0),_xlfn.XMATCH(S$2,Table2[#Headers],0))=0,"",INDEX(Table2[],_xlfn.XMATCH($A15,Table2[Steel Member],0),_xlfn.XMATCH(S$2,Table2[#Headers],0)))} -> Weight | T15: =IF(AND(ISBLANK(B15),ISBLANK(C15)),"","t") -> t | U15: =VLOOKUP(N15,'COLOR CODE'!$B:$D,2,FALSE) -> 0,0,255 | V15: =IF(AND(ISBLANK(B15),ISBLANK(C15)),"","Red") -> Red | W15: {=IF(INDEX(Table2[],_xlfn.XMATCH($A15,Table2[Steel Member],0),_xlfn.XMATCH(W$2,Table2[#Headers],0))=0,"",INDEX(Table2[],_xlfn.XMATCH($A15,Table2[Steel Member],0),_xlfn.XMATCH(W$2,Table2[#Headers],0)))} | X15: =W15 | Y15: {=IF(INDEX(Table2[],_xlfn.XMATCH($A15,Table2[Steel Member],0),_xlfn.XMATCH(Y$2,Table2[#Headers],0))=0,"",INDEX(Table2[],_xlfn.XMATCH($A15,Table2[Steel Member],0),_xlfn.XMATCH(Y$2,Table2[#Headers],0)))} -> "0 degrees" | Z15: {=IF(INDEX(Table2[],_xlfn.XMATCH($A15,Table2[Steel Member],0),_xlfn.XMATCH(Z$2,Table2[#Headers],0))=0,"",INDEX(Table2[],_xlfn.XMATCH($A15,Table2[Steel Member],0),_xlfn.XMATCH(Z$2,Table2[#Headers],0)))} | AA15: {=IF(INDEX(Table2[],_xlfn.XMATCH($A15,Table2[Steel Member],0),_xlfn.XMATCH(AA$2,Table2[#Headers],0))=0,"",INDEX(Table2[],_xlfn.XMATCH($A15,Table2[Steel Member],0),_xlfn.XMATCH(AA$2,Table2[#Headers],0)))} -> [Count] | AB15: {=IF(INDEX(Table2[],_xlfn.XMATCH($A15,Table2[Steel Member],0),_xlfn.XMATCH(AB$2,Table2[#Headers],0))=0,"",INDEX(Table2[],_xlfn.XMATCH($A15,Table2[Steel Member],0),_xlfn.XMATCH(AB$2,Table2[#Headers],0)))} -> [Length] | AC15: {=IFERROR(INDEX(Table8[],_xlfn.XMATCH($O15,Table8[Dimension Name Category],0),_xlfn.XMATCH(AC$2&IF($L15," w/ tag"," w/o tag"),Table8[#Headers],0)),"")} -> 4 | AD15: =IF(OR($AC15="",$AC15=0),"",IF($A15=Column,"{Length}*XNUMBER({Dimension Group Name},"&$AC15&")/1000","{Length}*XNUMBER({Dimension Group Name},"&$AC15&")/1000*{Slope Factor}")) -> {Length}*XNUMBER({Dimension Group Name},4)/1000*{Slope Factor} | AE15: =IF(AND(ISBLANK(B15),ISBLANK(C15)),"",IF($A15=Purlins_Girths_Bracings,"","Steel Surface Area")) -> Steel Surface Area | AF15: =IF(AND(ISBLANK(B15),ISBLANK(C15)),"",IF($A15=Purlins_Girths_Bracings,"","m2")) -> m2 | AG15: {=IFERROR(INDEX(Table8[],_xlfn.XMATCH($O15,Table8[Dimension Name Category],0),_xlfn.XMATCH(AG$2&IF($L15," w/ tag"," w/o tag"),Table8[#Headers],0)),"")} -> 5 | AH15: =IF(OR($AG15="",$AG15=0),"",IF($A15=Column,"{Length}*XNUMBER({Dimension Group Name},"&$AG15&")/1000","{Length}*XNUMBER({Dimension Group Name},"&$AG15&")/1000*{Slope Factor}")) -> {Length}*XNUMBER({Dimension Group Name},5)/1000*{Slope Factor} | AJ15: =IF(OR($A15=Column,$A15=""),"","Slope Length") -> Slope Length | AK15: =IF(OR($A15=Column,$A15=""),"","m") -> m | AL15: {=IF(INDEX(Table2[],_xlfn.XMATCH($A15,Table2[Steel Member],0),_xlfn.XMATCH(AL$2,Table2[#Headers],0))=0,"",INDEX(Table2[],_xlfn.XMATCH($A15,Table2[Steel Member],0),_xlfn.XMATCH(AL$2,Table2[#Headers],0)))} -> [Length]*{Slope Factor} | AN15: =IF(OR($A15=Column,$A15=""),"","Slope Factor") -> Slope Factor | AP15: {=IF(INDEX(Table2[],_xlfn.XMATCH($A15,Table2[Steel Member],0),_xlfn.XMATCH(AP$2,Table2[#Headers],0))=0,"",INDEX(Table2[],_xlfn.XMATCH($A15,Table2[Steel Member],0),_xlfn.XMATCH(AP$2,Table2[#Headers],0)))} -> 1/COS(RADIANS(XNUMBER({Dimension Name},1)))
