Workbook

Sheet Trade Breakup
A1: Bill Ref. | B1: Description | C1: Quantity | D1: Unit | E1: Rate | F1: Total
B2: GFA
B3: FECA
B4: Ground Floor | C4: =(2759)*(1)*(1)*(1)*(1 + (0)) | D4: m2 | F4: =C4*E4
B5: Level 1 | C5: =(974)*(1)*(1)*(1)*(1 + (0)) | D5: m2 | F5: =C5*E5
B6: UCA
B7: Ground Floor | C7: =(219)*(1)*(1)*(1)*(1 + (0)) | D7: m2 | F7: =C7*E7
B8: Level 1 | C8: =(68)*(1)*(1)*(1)*(1 + (0)) | D8: m2 | F8: =C8*E8
B9: External Area
B10: Ground Floor | C10: =(1896)*(1)*(1)*(1)*(1 + (0)) | D10: m2 | F10: =C10*E10
B11: Demolition
B12: GENERALLY
A13: 1/1A | B13: Tenderers are referred to the Specification for the full particulars of workmanship and materials, and the quantities herein provided shall be read in conjunction with the drawings | D13: Note | F13: =C13*E13
A14: 1/1B | B14: This Builders Bill of Quantities has not been measured in accordance with the Australian Standard Method of Measurement of Building Works, 5th Edition | D14: Note | F14: =C14*E14
A15: 1/1C | B15: The Tenderers should carefully check site to assess the extent of Demolition required for this contract | D15: Note | F15: =C15*E15
B16: REFERENCES
B17: Refer to drawing no. A.058-A for Demolition Plan | D17: Note | F17: =C17*E17
B18: PRICES
B19: Prices shall include for:
A20: 1/1D | B20: Demolition of work | D20: Note | F20: =C20*E20
A21: 1/1E | B21: Taking down, removal and cartage from site | D21: Note | F21: =C21*E21
A22: 1/1F | B22: Cleaning up on completion | D22: Note | F22: =C22*E22
A23: 1/1G | B23: Protecting adjoining surfaces | D23: Note | F23: =C23*E23
A24: 1/1H | B24: Making good to work disturbed | D24: Note | F24: =C24*E24
A25: 1/1J | B25: Recycling waste where required | D25: Note | F25: =C25*E25
A26: 1/1K | B26: Tip fees | D26: Note | F26: =C26*E26
A27: 1/1L | B27: Environmental and sustainable requirements detailed in the specification | D27: Note | F27: =C27*E27
B28: GENERAL ITEMS
A29: 1/1M | B29: Allow for site visit to assess the nature and extent of demolition | C29: =(1)*(1)*(1)*(1)*(1 + (0)) | D29: Item | F29: =C29*E29
A30: D/10A | B30: Allow to remove all vegetation within the demolition zone for the new buildings and associated paths including those not specifically noted on the drawings | C30: =(1)*(1)*(1)*(1)*(1 + (0)) | D30: Item | F30: =C30*E30
A31: 1/1N | B31: Allow to retain and protect existing works / premises on site and adjoining properties | C31: =(1)*(1)*(1)*(1)*(1 + (0)) | D31: Item | F31: =C31*E31
A32: 1/2A | B32: Allow for provision and removal of temporary fencing / screens, hoardings, weather / dust protection measures, security, temporary access, warning notices and the like | C32: =(1)*(1)*(1)*(1)*(1 + (0)) | D32: Item | F32: =C32*E32
A33: 1/2B | B33: Allow for all temporary shoring, propping, supports and the like (other than designed shoring and propping measured following) | C33: =(1)*(1)*(1)*(1)*(1 + (0)) | D33: Item | F33: =C33*E33
A34: 1/2C | B34: Allow for all required credits for recovered materials | C34: =(1)*(1)*(1)*(1)*(1 + (0)) | D34: Item | F34: =C34*E34
A35: 1/2D | B35: Allow for giving notice of any unanticipated hazardous materials or conditions found on site | C35: =(1)*(1)*(1)*(1)*(1 + (0)) | D35: Item | F35: =C35*E35
A36: 1/2E | B36: Allow for giving notice of and providing facilities for inspection | C36: =(1)*(1)*(1)*(1)*(1 + (0)) | D36: Item | F36: =C36*E36
A37: 1/2F | B37: Allow for compliance with quality assurance requirements | C37: =(1)*(1)*(1)*(1)*(1 + (0)) | D37: Item | F37: =C37*E37
A38: 1/2G | B38: Allow for submissions including work plans, data and dilapidation records | C38: =(1)*(1)*(1)*(1)*(1 + (0)) | D38: Item | F38: =C38*E38
A39: 1/2H | B39: Allow for traffic management measures | C39: =(1)*(1)*(1)*(1)*(1 + (0)) | D39: Item | F39: =C39*E39
A40: 1/2J | B40: Allow for all costs associated with meeting local authority requirements and obtaining approvals | C40: =(1)*(1)*(1)*(1)*(1 + (0)) | D40: Item | F40: =C40*E40
...

Sheet Trade Breakup Showing Markup
A1: Bill Ref. | B1: Description | C1: Quantity | D1: Unit | E1: Rate | F1: Markup | G1: Total
B2: GFA
B3: FECA
B4: Ground Floor | C4: =(2759)*(1)*(1)*(1)*(1 + (0)) | D4: m2 | F4: =(0) | G4: =(C4 * E4 + C4 * E4 * F4)
B5: Level 1 | C5: =(974)*(1)*(1)*(1)*(1 + (0)) | D5: m2 | F5: =(0) | G5: =(C5 * E5 + C5 * E5 * F5)
B6: UCA
B7: Ground Floor | C7: =(219)*(1)*(1)*(1)*(1 + (0)) | D7: m2 | F7: =(0) | G7: =(C7 * E7 + C7 * E7 * F7)
B8: Level 1 | C8: =(68)*(1)*(1)*(1)*(1 + (0)) | D8: m2 | F8: =(0) | G8: =(C8 * E8 + C8 * E8 * F8)
B9: External Area
B10: Ground Floor | C10: =(1896)*(1)*(1)*(1)*(1 + (0)) | D10: m2 | F10: =(0) | G10: =(C10 * E10 + C10 * E10 * F10)
B11: Demolition
B12: GENERALLY
A13: 1/1A | B13: Tenderers are referred to the Specification for the full particulars of workmanship and materials, and the quantities herein provided shall be read in conjunction with the drawings | D13: Note | F13: =(0) | G13: =(C13 * E13 + C13 * E13 * F13)
A14: 1/1B | B14: This Builders Bill of Quantities has not been measured in accordance with the Australian Standard Method of Measurement of Building Works, 5th Edition | D14: Note | F14: =(0) | G14: =(C14 * E14 + C14 * E14 * F14)
A15: 1/1C | B15: The Tenderers should carefully check site to assess the extent of Demolition required for this contract | D15: Note | F15: =(0) | G15: =(C15 * E15 + C15 * E15 * F15)
B16: REFERENCES
B17: Refer to drawing no. A.058-A for Demolition Plan | D17: Note | F17: =(0) | G17: =(C17 * E17 + C17 * E17 * F17)
B18: PRICES
B19: Prices shall include for:
A20: 1/1D | B20: Demolition of work | D20: Note | F20: =(0) | G20: =(C20 * E20 + C20 * E20 * F20)
A21: 1/1E | B21: Taking down, removal and cartage from site | D21: Note | F21: =(0) | G21: =(C21 * E21 + C21 * E21 * F21)
A22: 1/1F | B22: Cleaning up on completion | D22: Note | F22: =(0) | G22: =(C22 * E22 + C22 * E22 * F22)
A23: 1/1G | B23: Protecting adjoining surfaces | D23: Note | F23: =(0) | G23: =(C23 * E23 + C23 * E23 * F23)
A24: 1/1H | B24: Making good to work disturbed | D24: Note | F24: =(0) | G24: =(C24 * E24 + C24 * E24 * F24)
A25: 1/1J | B25: Recycling waste where required | D25: Note | F25: =(0) | G25: =(C25 * E25 + C25 * E25 * F25)
A26: 1/1K | B26: Tip fees | D26: Note | F26: =(0) | G26: =(C26 * E26 + C26 * E26 * F26)
A27: 1/1L | B27: Environmental and sustainable requirements detailed in the specification | D27: Note | F27: =(0) | G27: =(C27 * E27 + C27 * E27 * F27)
B28: GENERAL ITEMS
A29: 1/1M | B29: Allow for site visit to assess the nature and extent of demolition | C29: =(1)*(1)*(1)*(1)*(1 + (0)) | D29: Item | F29: =(0) | G29: =(C29 * E29 + C29 * E29 * F29)
A30: D/10A | B30: Allow to remove all vegetation within the demolition zone for the new buildings and associated paths including those not specifically noted on the drawings | C30: =(1)*(1)*(1)*(1)*(1 + (0)) | D30: Item | F30: =(0) | G30: =(C30 * E30 + C30 * E30 * F30)
A31: 1/1N | B31: Allow to retain and protect existing works / premises on site and adjoining properties | C31: =(1)*(1)*(1)*(1)*(1 + (0)) | D31: Item | F31: =(0) | G31: =(C31 * E31 + C31 * E31 * F31)
A32: 1/2A | B32: Allow for provision and removal of temporary fencing / screens, hoardings, weather / dust protection measures, security, temporary access, warning notices and the like | C32: =(1)*(1)*(1)*(1)*(1 + (0)) | D32: Item | F32: =(0) | G32: =(C32 * E32 + C32 * E32 * F32)
A33: 1/2B | B33: Allow for all temporary shoring, propping, supports and the like (other than designed shoring and propping measured following) | C33: =(1)*(1)*(1)*(1)*(1 + (0)) | D33: Item | F33: =(0) | G33: =(C33 * E33 + C33 * E33 * F33)
A34: 1/2C | B34: Allow for all required credits for recovered materials | C34: =(1)*(1)*(1)*(1)*(1 + (0)) | D34: Item | F34: =(0) | G34: =(C34 * E34 + C34 * E34 * F34)
A35: 1/2D | B35: Allow for giving notice of any unanticipated hazardous materials or conditions found on site | C35: =(1)*(1)*(1)*(1)*(1 + (0)) | D35: Item | F35: =(0) | G35: =(C35 * E35 + C35 * E35 * F35)
A36: 1/2E | B36: Allow for giving notice of and providing facilities for inspection | C36: =(1)*(1)*(1)*(1)*(1 + (0)) | D36: Item | F36: =(0) | G36: =(C36 * E36 + C36 * E36 * F36)
A37: 1/2F | B37: Allow for compliance with quality assurance requirements | C37: =(1)*(1)*(1)*(1)*(1 + (0)) | D37: Item | F37: =(0) | G37: =(C37 * E37 + C37 * E37 * F37)
A38: 1/2G | B38: Allow for submissions including work plans, data and dilapidation records | C38: =(1)*(1)*(1)*(1)*(1 + (0)) | D38: Item | F38: =(0) | G38: =(C38 * E38 + C38 * E38 * F38)
A39: 1/2H | B39: Allow for traffic management measures | C39: =(1)*(1)*(1)*(1)*(1 + (0)) | D39: Item | F39: =(0) | G39: =(C39 * E39 + C39 * E39 * F39)
A40: 1/2J | B40: Allow for all costs associated with meeting local authority requirements and obtaining approvals | C40: =(1)*(1)*(1)*(1)*(1 + (0)) | D40: Item | F40: =(0) | G40: =(C40 * E40 + C40 * E40 * F40)
...

Sheet Trade Summary
A1: Description | B1: Job % | C1: Cost per Unit | D1: Total
A2: GFA | D2: =SUBTOTAL(9,'Trade Breakup Showing Markup'!G$2:G$10)
A3: Demolition | D3: =SUBTOTAL(9,'Trade Breakup Showing Markup'!G$11:G$56)
A4: Groundworks | D4: =SUBTOTAL(9,'Trade Breakup Showing Markup'!G$57:G$127)
A5: Piling | D5: =SUBTOTAL(9,'Trade Breakup Showing Markup'!G$128:G$157)
A6: Concrete | D6: =SUBTOTAL(9,'Trade Breakup Showing Markup'!G$158:G$304)
A7: Formwork | D7: =SUBTOTAL(9,'Trade Breakup Showing Markup'!G$305:G$429)
A8: Reinforcement | D8: =SUBTOTAL(9,'Trade Breakup Showing Markup'!G$430:G$543)
A9: Precast Concrete | D9: =SUBTOTAL(9,'Trade Breakup Showing Markup'!G$544:G$583)
A10: Structural Steel | D10: =SUBTOTAL(9,'Trade Breakup Showing Markup'!G$584:G$797)
A11: Waterproofing | D11: =SUBTOTAL(9,'Trade Breakup Showing Markup'!G$798:G$852)
A12: Masonry | D12: =SUBTOTAL(9,'Trade Breakup Showing Markup'!G$853:G$1116)
A13: Metalworks | D13: =SUBTOTAL(9,'Trade Breakup Showing Markup'!G$1117:G$1196)
A14: Roofing | D14: =SUBTOTAL(9,'Trade Breakup Showing Markup'!G$1197:G$1263)
A15: Cladding & Louvres | D15: =SUBTOTAL(9,'Trade Breakup Showing Markup'!G$1264:G$1332)
A16: Glazing, Windows & Glazed Doors | D16: =SUBTOTAL(9,'Trade Breakup Showing Markup'!G$1333:G$1441)
A17: Doors and Door Hardware | D17: =SUBTOTAL(9,'Trade Breakup Showing Markup'!G$1442:G$1555)
A18: Partitions & Linings | D18: =SUBTOTAL(9,'Trade Breakup Showing Markup'!G$1556:G$1781)
A19: Ceilings | D19: =SUBTOTAL(9,'Trade Breakup Showing Markup'!G$1782:G$1836)
A20: Carpet | D20: =SUBTOTAL(9,'Trade Breakup Showing Markup'!G$1837:G$1866)
A21: Resilient Finishes | D21: =SUBTOTAL(9,'Trade Breakup Showing Markup'!G$1867:G$1923)
A22: Tiling | D22: =SUBTOTAL(9,'Trade Breakup Showing Markup'!G$1924:G$1967)
A23: Painting | D23: =SUBTOTAL(9,'Trade Breakup Showing Markup'!G$1968:G$2034)
A24: FF&E (Group 1 & 2) | D24: =SUBTOTAL(9,'Trade Breakup Showing Markup'!G$2035:G$2147)
A25: White Goods | D25: =SUBTOTAL(9,'Trade Breakup Showing Markup'!G$2148:G$2186)
A26: Signage | D26: =SUBTOTAL(9,'Trade Breakup Showing Markup'!G$2187:G$2244)
A27: Joinery | D27: =SUBTOTAL(9,'Trade Breakup Showing Markup'!G$2245:G$2300)
A28: Hydraulic Services | D28: =SUBTOTAL(9,'Trade Breakup Showing Markup'!G$2301:G$2326)
A29: Electrical & Security Services | D29: =SUBTOTAL(9,'Trade Breakup Showing Markup'!G$2327:G$2349)
A30: Mechanical Services | D30: =SUBTOTAL(9,'Trade Breakup Showing Markup'!G$2350:G$2368)
A31: Fire Services | D31: =SUBTOTAL(9,'Trade Breakup Showing Markup'!G$2369:G$2389)
A32: Vertical Transport | D32: =SUBTOTAL(9,'Trade Breakup Showing Markup'!G$2390:G$2407)
A33: External Works | D33: =SUBTOTAL(9,'Trade Breakup Showing Markup'!G$2408:G$2533)
A34: External Services | D34: =SUBTOTAL(9,'Trade Breakup Showing Markup'!G$2534:G$2560)
A35: Timber/Wood | D35: =SUBTOTAL(9,'Trade Breakup Showing Markup'!G$2561:G$2589)
A36: Provisional Sums | B36: 100 | D36: =SUBTOTAL(9,'Trade Breakup Showing Markup'!G$2590:G$2593)
D37: =SUBTOTAL(9,'Trade Breakup Showing Markup'!G$2594:G$2594)
A38: Subtotal | D38: ='Trade Breakup Showing Markup'!G2596
A39: Adjustment | D39: ='Trade Breakup Showing Markup'!G2597
A40: G.S.T | D40: ='Trade Breakup Showing Markup'!G2598
...
